Workbook

Sheet Infos+
A1: Info

Sheet Plate organization+
A1: mtp_dna_stocks
A2: Plate I | B2: 1 | C2: 2 | D2: 3 | E2: 4 | F2: 5 | G2: 6 | H2: 7 | I2: 8 | J2: 9 | K2: 10 | L2: 11 | M2: 12
A3: A | B3: Psyn | C3: PH36
A4: B | B4: RBS
A5: C | B5: aroF_S188C | C5: aroC
A6: D | B6: TrrnB
A7: E | B7: DVK_AE
A8: F
A9: G
A10: H
A13: mtp_mastermix
A14: Plate I | B14: 1 | C14: 2 | D14: 3 | E14: 4 | F14: 5 | G14: 6 | H14: 7 | I14: 8 | J14: 9 | K14: 10 | L14: 11 | M14: 12
A15: A | B15: Mastermix1
A16: B
A17: C
A18: D
A19: E
A20: F
A21: G
A22: H
A25: mtp_source | B25: Complete occupancy | C25: Diluted parts in mtp_source need to be in the same well as in mtp_dna_stocks (do not change the well positions of parts in mtp_source)
A26: Plate I | B26: 1 | C26: 2 | D26: 3 | E26: 4 | F26: 5 | G26: 6 | H26: 7 | I26: 8 | J26: 9 | K26: 10 | L26: 11 | M26: 12
A27: A | B27: Psyn | C27: PH36
A28: B | B28: RBS
A29: C | B29: aroF_S188C | C29: aroC
A30: D | B30: TrrnB
A31: E | B31: DVK_AE
A32: F
A33: G
A34: H | B34: Plasmidmix1
B36: Only change cells in blue
A37: Meta data | B37: Value | E37: GGA Mastermix Calculator | I37: Plasmidmix Well check | K37: Outputs wells for Plasmidmixes from "PM_info+" sheet
A38: Volume per Part per reaction [µL] | B38: 2 | C38: =IF(B38,"","<-- Value missing") | E38: BsaI (U/rxn) | F38: 10 | G38: 10 U per reaction standardly used | I38: {=_xlfn.UNIQUE(_xlfn._xlws.FILTER('PM_info+'!$C$2:$C$97,'PM_info+'!$C$2:$C$97<>""))} -> Plasmidmix1 | J38: {=IF(I38="","",_xlfn.TEXTJOIN(", ",TRUE,_xlfn._xlws.FILTER('PM_info+'!$B$2:$B$97,('PM_info+'!$C$2:$C$97=I38)*('PM_info+'!$C$2:$C$97<>""),"")))} -> H01 | K38: Put "Plasmidmix#" in the indicated wells in "mtp_source"
A39: Volume Mastermix total [µL] | E39: T4 Ligase (U/rxn) | F39: 100 | G39: 100 U per reaction standardly used | J39: {=IF(I39="","",_xlfn.TEXTJOIN(", ",TRUE,_xlfn._xlws.FILTER('PM_info+'!$B$2:$B$97,('PM_info+'!$C$2:$C$97=I39)*('PM_info+'!$C$2:$C$97<>""),"")))}
A40: Volume Mastermix per reaction [µL] | B40: =0.2*B45 -> 4 | C40: =IF(B40,"","<-- Value missing") | E40: Number Reactions | F40: 1 | J40: {=IF(I40="","",_xlfn.TEXTJOIN(", ",TRUE,_xlfn._xlws.FILTER('PM_info+'!$B$2:$B$97,('PM_info+'!$C$2:$C$97=I40)*('PM_info+'!$C$2:$C$97<>""),"")))}
A41: Part concentration [fmol/µL] | B41: 10 | C41: Actually depends on column in "DNA_dilution+" sheet | E41: BsaI (20 U/ul) | F41: =(F38/20)*F40*(B45/30) -> 0.33333333 | J41: {=IF(I41="","",_xlfn.TEXTJOIN(", ",TRUE,_xlfn._xlws.FILTER('PM_info+'!$B$2:$B$97,('PM_info+'!$C$2:$C$97=I41)*('PM_info+'!$C$2:$C$97<>""),"")))}
A42: Mol per part and reaction [fmol] | B42: =B38*B41 -> 20 | C42: Auto calculation | E42: T4 DNA ligase (400 U/ul) | F42: =(F39/400)*F40*(B45/30) -> 0.16666667 | J42: {=IF(I42="","",_xlfn.TEXTJOIN(", ",TRUE,_xlfn._xlws.FILTER('PM_info+'!$B$2:$B$97,('PM_info+'!$C$2:$C$97=I42)*('PM_info+'!$C$2:$C$97<>""),"")))}
A43: Volume per Part in Plasmidmix [µL] | B43: 15 | C43: =IF(B43,"","<-- Value missing") | E43: 10x ligase buffer | F43: =(B45/10)*F40 -> 2 | J43: {=IF(I43="","",_xlfn.TEXTJOIN(", ",TRUE,_xlfn._xlws.FILTER('PM_info+'!$B$2:$B$97,('PM_info+'!$C$2:$C$97=I43)*('PM_info+'!$C$2:$C$97<>""),"")))}
A44: Volume Plasmidprep Plate per well [µL] | B44: 0 | E44: 100x BSA | F44: =0.004*B45*F40 -> 0.08 | J44: {=IF(I44="","",_xlfn.TEXTJOIN(", ",TRUE,_xlfn._xlws.FILTER('PM_info+'!$B$2:$B$97,('PM_info+'!$C$2:$C$97=I44)*('PM_info+'!$C$2:$C$97<>""),"")))}
A45: Total Volume per reaction | B45: 20 | C45: =IF(B45,"","<-- Value missing") | E45: H2O | F45: =(B40*F40)-SUM(F41:F44) -> 1.42 | J45: {=IF(I45="","",_xlfn.TEXTJOIN(", ",TRUE,_xlfn._xlws.FILTER('PM_info+'!$B$2:$B$97,('PM_info+'!$C$2:$C$97=I45)*('PM_info+'!$C$2:$C$97<>""),"")))}
...

Sheet Plan+
A1: Nr. | B1: Mastermix | C1: Backbone | D1: Promotor | E1: RBS | F1: Signal Peptide | G1: GoI | H1: Tag/Term | I1: Plasmidmix | J1: Water | K1: Well | L1: Plate | M1: Description
A2: 1 | B2: Mastermix1 | D2: Psyn | E2: RBS | G2: aroF_S188C | I2: Plasmidmix1 | J2: water | K2: A01 | L2: Destination_Plate_1
A3: 2 | B3: Mastermix1 | D3: Psyn | E3: RBS | G3: aroC | I3: Plasmidmix1 | J3: water | K3: B01 | L3: Destination_Plate_1
A4: 3 | B4: Mastermix1 | D4: PH36 | E4: RBS | G4: aroF_S188C | I4: Plasmidmix1 | J4: water | K4: C01 | L4: Destination_Plate_1
A5: 4 | B5: Mastermix1 | D5: PH36 | E5: RBS | G5: aroC | I5: Plasmidmix1 | J5: water | K5: D01 | L5: Destination_Plate_1
A6: 5 | K6: E01 | L6: Destination_Plate_1
A7: 6 | K7: F01 | L7: Destination_Plate_1
A8: 7 | K8: G01 | L8: Destination_Plate_1
A9: 8 | K9: H01 | L9: Destination_Plate_1
A10: 9 | K10: A02 | L10: Destination_Plate_1
A11: 10 | K11: B02 | L11: Destination_Plate_1
A12: 11 | K12: C02 | L12: Destination_Plate_1
A13: 12 | K13: D02 | L13: Destination_Plate_1
A14: 13 | K14: E02 | L14: Destination_Plate_1
A15: 14 | K15: F02 | L15: Destination_Plate_1
A16: 15 | K16: G02 | L16: Destination_Plate_1
A17: 16 | K17: H02 | L17: Destination_Plate_1
... A97: 96 | K97: H12 | L97: Destination_Plate_1

Sheet PM_info+
A1: MTP_source | B1: Well | C1: Plasmidmix Nr. | D1: PM1 | E1: PM2 | F1: PM3 | G1: PM4 | H1: Check that the plasmid mixes are in the same well as in the "mtp_source" plate in the "Plate organization+" sheet
A2: 1 | B2: A01
A3: 2 | B3: B01 | H3: Do not select cells and move them to different rows! Only type manually or use copy & paste
A4: 3 | B4: C01
A5: 4 | B5: D01
A6: 5 | B6: E01
A7: 6 | B7: F01
A8: 7 | B8: G01
A9: 8 | B9: H01 | C9: Plasmidmix1 | D9: RBS | E9: TrrnB | F9: DVK_AE
A10: 9 | B10: A02
A11: 10 | B11: B02
A12: 11 | B12: C02
A13: 12 | B13: D02
A14: 13 | B14: E02
A15: 14 | B15: F02
A16: 15 | B16: G02
A17: 16 | B17: H02
A18: 17 | B18: A03
A19: 18 | B19: B03
A20: 19 | B20: C03
A21: 20 | B21: D03
... A97: 96 | B97: H12

Sheet DNA_dilution+
A1: Location | B1: 260 Raw | C1: 280 Raw | D1: 320 Raw | E1: 260 | F1: 280 | G1: 260/280 | H1: Description | I1: ng/µL | J1: bp | K1: DNA amount [ng] in 1 ul | L1: Volume [ul] | M1: Volume to resuspend | N1: Molarity | O1: Sample | P1: Seq Ref | Q1: Primer | R1: Seq results | S1: Well
A2: =IF(I2="","",S2) -> A01 | B2: 0.398 | C2: 0.221 | D2: 0.039 | E2: 0.355 | F2: 0.179 | G2: 1.978 | H2: =Source_Plate!A2 -> Psyn | I2: 75 | J2: 2142 | K2: =(N2*1000)*(617.96*J2+36.04)/1000000000 -> 13.237064 | L2: =IFERROR((K2/I2)*M2," ") -> 17.649418 | M2: 100 | N2: 10 | S2: A01
A3: =IF(I3="","",S3) -> B01 | B3: 0.534 | C3: 0.28 | D3: 0.042 | E3: 0.492 | F3: 0.237 | G3: 2.079 | H3: =Source_Plate!A3 -> RBS | I3: 143 | J3: 2142 | K3: =(N3*1000)*(617.96*J3+36.04)/1000000000 -> 13.237064 | L3: =IFERROR((K3/I3)*M3," ") -> 9.2566878 | M3: 100 | N3: 10 | S3: B01
A4: =IF(I4="","",S4) -> C01 | B4: 0.385 | C4: 0.221 | D4: 0.05 | E4: 0.331 | F4: 0.168 | G4: 1.971 | H4: =Source_Plate!A4 -> aroF_S188C | I4: 179 | J4: 3206 | K4: =(N4*1000)*(617.96*J4+36.04)/1000000000 -> 19.812158 | L4: =IFERROR((K4/I4)*M4," ") -> 11.068245 | M4: 100 | N4: 10 | S4: C01
A5: =IF(I5="","",S5) -> D01 | B5: 0.476 | C5: 0.366 | D5: 0.15 | E5: 0.322 | F5: 0.214 | G5: 1.508 | H5: =Source_Plate!A5 -> TrrnB | I5: 63 | J5: 2341 | K5: =(N5*1000)*(617.96*J5+36.04)/1000000000 -> 14.466804 | L5: =IFERROR((K5/I5)*M5," ") -> 22.963181 | M5: 100 | N5: 10 | S5: D01
A6: =IF(I6="","",S6) -> E01 | B6: 0.587 | C6: 0.324 | D6: 0.073 | E6: 0.509 | F6: 0.248 | G6: 2.055 | H6: =Source_Plate!A6 -> DVK_AE | I6: 120 | J6: 40 | K6: =(N6*1000)*(617.96*J6+36.04)/1000000000 -> 0.2475444 | L6: =IFERROR((K6/I6)*M6," ") -> 0.206287 | M6: 100 | N6: 10 | S6: E01
A7: =IF(I7="","",S7) | B7: 0.292 | C7: 0.167 | D7: 0.039 | E7: 0.248 | F7: 0.125 | G7: 1.982 | H7: =Source_Plate!A7 | K7: =(N7*1000)*(617.96*J7+36.04)/1000000000 -> 0.0003604 | L7: =IFERROR((K7/I7)*M7," ") | M7: 100 | N7: 10 | S7: F01
A8: =IF(I8="","",S8) | B8: 0.049 | C8: 0.045 | D8: 0.039 | E8: 0.006 | F8: 0.004 | G8: 1.645 | H8: =Source_Plate!A8 | K8: =(N8*1000)*(617.96*J8+36.04)/1000000000 -> 0.0003604 | L8: =IFERROR((K8/I8)*M8," ") | M8: 100 | N8: 10 | S8: G01
A9: =IF(I9="","",S9) | B9: 0.142 | C9: 0.091 | D9: 0.038 | E9: 0.1 | F9: 0.05 | G9: 1.983 | H9: =Source_Plate!A9 | K9: =(N9*1000)*(617.96*J9+36.04)/1000000000 -> 0.0003604 | L9: =IFERROR((K9/I9)*M9," ") | M9: 100 | N9: 10 | S9: H01
A10: =IF(I10="","",S10) -> A02 | B10: 0.39 | C10: 0.209 | D10: 0.039 | E10: 0.341 | F10: 0.164 | G10: 2.074 | H10: =Source_Plate!A10 -> PH36 | I10: 86 | J10: 2197 | K10: =(N10*1000)*(617.96*J10+36.04)/1000000000 -> 13.576942 | L10: =IFERROR((K10/I10)*M10," ") -> 15.787141 | M10: 100 | N10: 10 | S10: A02
A11: =IF(I11="","",S11) | B11: 0.289 | C11: 0.179 | D11: 0.069 | E11: 0.21 | F11: 0.105 | G11: 2.009 | H11: =Source_Plate!A11 | K11: =(N11*1000)*(617.96*J11+36.04)/1000000000 -> 0.0003604 | L11: =IFERROR((K11/I11)*M11," ") | M11: 100 | N11: 10 | S11: B02
A12: =IF(I12="","",S12) -> C02 | B12: 0.26 | C12: 0.162 | D12: 0.046 | E12: 0.204 | F12: 0.11 | G12: 1.855 | H12: =Source_Plate!A12 -> aroC | I12: 308 | J12: 3329 | K12: =(N12*1000)*(617.96*J12+36.04)/1000000000 -> 20.572249 | L12: =IFERROR((K12/I12)*M12," ") -> 6.6793016 | M12: 100 | N12: 10 | S12: C02
A13: =IF(I13="","",S13) | B13: 0.257 | C13: 0.149 | D13: 0.039 | E13: 0.208 | F13: 0.104 | G13: 1.989 | H13: =Source_Plate!A13 | K13: =(N13*1000)*(617.96*J13+36.04)/1000000000 -> 0.0003604 | L13: =IFERROR((K13/I13)*M13," ") | M13: 100 | N13: 10 | S13: D02
A14: =IF(I14="","",S14) | B14: 0.413 | C14: 0.255 | D14: 0.077 | E14: 0.32 | F14: 0.169 | G14: 1.893 | H14: =Source_Plate!A14 | K14: =(N14*1000)*(617.96*J14+36.04)/1000000000 -> 0.0003604 | L14: =IFERROR((K14/I14)*M14," ") | M14: 100 | N14: 10 | S14: E02
A15: =IF(I15="","",S15) | B15: 0.411 | C15: 0.317 | D15: 0.222 | E15: 0.179 | F15: 0.089 | G15: 2.003 | H15: =Source_Plate!A15 | K15: =(N15*1000)*(617.96*J15+36.04)/1000000000 -> 0.0003604 | L15: =IFERROR((K15/I15)*M15," ") | M15: 100 | N15: 10 | S15: F02
A16: =IF(I16="","",S16) | B16: 0.317 | C16: 0.264 | D16: 0.192 | E16: 0.117 | F16: 0.067 | G16: 1.74 | H16: =Source_Plate!A16 | K16: =(N16*1000)*(617.96*J16+36.04)/1000000000 -> 0.0003604 | L16: =IFERROR((K16/I16)*M16," ") | M16: 100 | N16: 10 | S16: G02
A17: =IF(I17="","",S17) | B17: 0.483 | C17: 0.338 | D17: 0.151 | E17: 0.319 | F17: 0.18 | G17: 1.779 | H17: =Source_Plate!A17 | K17: =(N17*1000)*(617.96*J17+36.04)/1000000000 -> 0.0003604 | L17: =IFERROR((K17/I17)*M17," ") | M17: 100 | N17: 10 | S17: H02
A18: =IF(I18="","",S18) | B18: 0.375 | C18: 0.202 | D18: 0.041 | E18: 0.324 | F18: 0.155 | G18: 2.089 | H18: =Source_Plate!A18 | K18: =(N18*1000)*(617.96*J18+36.04)/1000000000 -> 0.0003604 | L18: =IFERROR((K18/I18)*M18," ") | M18: 100 | N18: 10 | S18: A03
A19: =IF(I19="","",S19) | B19: 0.153 | C19: 0.097 | D19: 0.038 | E19: 0.108 | F19: 0.055 | G19: 1.98 | H19: =Source_Plate!A19 | K19: =(N19*1000)*(617.96*J19+36.04)/1000000000 -> 0.0003604 | L19: =IFERROR((K19/I19)*M19," ") | M19: 100 | N19: 10 | S19: B03
A20: =IF(I20="","",S20) | B20: 0.535 | C20: 0.292 | D20: 0.058 | E20: 0.458 | F20: 0.224 | G20: 2.042 | H20: =Source_Plate!A20 | K20: =(N20*1000)*(617.96*J20+36.04)/1000000000 -> 0.0003604 | L20: =IFERROR((K20/I20)*M20," ") | M20: 100 | N20: 10 | S20: C03
A21: =IF(I21="","",S21) | B21: 0.227 | C21: 0.141 | D21: 0.052 | E21: 0.165 | F21: 0.083 | G21: 1.979 | H21: =Source_Plate!A21 | K21: =(N21*1000)*(617.96*J21+36.04)/1000000000 -> 0.0003604 | L21: =IFERROR((K21/I21)*M21," ") | M21: 100 | N21: 10 | S21: D03
A22: =IF(I22="","",S22) | B22: 0.238 | C22: 0.14 | D22: 0.043 | E22: 0.185 | F22: 0.091 | G22: 2.023 | H22: =Source_Plate!A22 | K22: =(N22*1000)*(617.96*J22+36.04)/1000000000 -> 0.0003604 | L22: =IFERROR((K22/I22)*M22," ") | M22: 100 | N22: 10 | S22: E03
A23: =IF(I23="","",S23) | B23: 0.445 | C23: 0.239 | D23: 0.038 | E23: 0.388 | F23: 0.191 | G23: 2.035 | H23: =Source_Plate!A23 | K23: =(N23*1000)*(617.96*J23+36.04)/1000000000 -> 0.0003604 | L23: =IFERROR((K23/I23)*M23," ") | M23: 100 | N23: 10 | S23: F03
A24: =IF(I24="","",S24) | B24: 0.495 | C24: 0.259 | D24: 0.039 | E24: 0.436 | F24: 0.21 | G24: 2.079 | H24: =Source_Plate!A24 | K24: =(N24*1000)*(617.96*J24+36.04)/1000000000 -> 0.0003604 | L24: =IFERROR((K24/I24)*M24," ") | M24: 100 | N24: 10 | S24: G03
... A73: =IF(I73="","",S73) | B73: 0.593 | C73: 0.317 | D73: 0.041 | E73: 0.533 | F73: 0.266 | G73: 2.002 | H73: =Source_Plate!A73 | K73: =(N73*1000)*(617.96*J73+36.04)/1000000000 -> 0.0001802 | L73: =IFERROR((K73/I73)*M73," ") | M73: 100 | N73: 5 | S73: H09
A74: =IF(I74="","",S74) | H74: =Source_Plate!A74 | K74: =(N74*1000)*(617.96*J74+36.04)/1000000000 -> 0.0001802 | L74: =IFERROR((K74/I74)*M74," ") | M74: 100 | N74: 5 | S74: A10
A75: =IF(I75="","",S75) | H75: =Source_Plate!A75 | K75: =(N75*1000)*(617.96*J75+36.04)/1000000000 -> 0.0001802 | L75: =IFERROR((K75/I75)*M75," ") | M75: 100 | N75: 5 | S75: B10
A76: =IF(I76="","",S76) | H76: =Source_Plate!A76 | K76: =(N76*1000)*(617.96*J76+36.04)/1000000000 -> 0.0001802 | L76: =IFERROR((K76/I76)*M76," ") | M76: 100 | N76: 5 | S76: C10
A77: =IF(I77="","",S77) | H77: =Source_Plate!A77 | K77: =(N77*1000)*(617.96*J77+36.04)/1000000000 -> 0.0001802 | L77: =IFERROR((K77/I77)*M77," ") | M77: 100 | N77: 5 | S77: D10
A78: =IF(I78="","",S78) | H78: =Source_Plate!A78 | K78: =(N78*1000)*(617.96*J78+36.04)/1000000000 -> 0.0001802 | L78: =IFERROR((K78/I78)*M78," ") | M78: 100 | N78: 5 | S78: E10
A79: =IF(I79="","",S79) | H79: =Source_Plate!A79 | K79: =(N79*1000)*(617.96*J79+36.04)/1000000000 -> 0.0001802 | L79: =IFERROR((K79/I79)*M79," ") | M79: 100 | N79: 5 | S79: F10
A80: =IF(I80="","",S80) | H80: =Source_Plate!A80 | K80: =(N80*1000)*(617.96*J80+36.04)/1000000000 -> 0.0001802 | L80: =IFERROR((K80/I80)*M80," ") | M80: 100 | N80: 5 | S80: G10
A81: =IF(I81="","",S81) | H81: =Source_Plate!A81 | K81: =(N81*1000)*(617.96*J81+36.04)/1000000000 -> 0.0001802 | L81: =IFERROR((K81/I81)*M81," ") | M81: 100 | N81: 5 | S81: H10
A82: =IF(I82="","",S82) | H82: =Source_Plate!A82 | K82: =(N82*1000)*(617.96*J82+36.04)/1000000000 -> 0.0001802 | L82: =IFERROR((K82/I82)*M82," ") | N82: 5 | S82: A11
A83: =IF(I83="","",S83) | H83: =Source_Plate!A83 | K83: =(N83*1000)*(617.96*J83+36.04)/1000000000 -> 0.0001802 | L83: =IFERROR((K83/I83)*M83," ") | N83: 5 | S83: B11
A84: =IF(I84="","",S84) | H84: =Source_Plate!A84 | K84: =(N84*1000)*(617.96*J84+36.04)/1000000000 -> 0.0001802 | L84: =IFERROR((K84/I84)*M84," ") | N84: 5 | S84: C11
A85: =IF(I85="","",S85) | H85: =Source_Plate!A85 | K85: =(N85*1000)*(617.96*J85+36.04)/1000000000 -> 0.0001802 | L85: =IFERROR((K85/I85)*M85," ") | N85: 5 | S85: D11
A86: =IF(I86="","",S86) | H86: =Source_Plate!A86 | K86: =(N86*1000)*(617.96*J86+36.04)/1000000000 -> 0.0001802 | L86: =IFERROR((K86/I86)*M86," ") | N86: 5 | S86: E11
A87: =IF(I87="","",S87) | H87: =Source_Plate!A87 | K87: =(N87*1000)*(617.96*J87+36.04)/1000000000 -> 0.0001802 | L87: =IFERROR((K87/I87)*M87," ") | N87: 5 | S87: F11
A88: =IF(I88="","",S88) | H88: =Source_Plate!A88 | K88: =(N88*1000)*(617.96*J88+36.04)/1000000000 -> 0.0001802 | L88: =IFERROR((K88/I88)*M88," ") | N88: 5 | S88: G11
...

Sheet Source_Plate
A1: Content | B1: Well | C1: MTP | E1: Content | F1: Well | G1: MTP | I1: Content | J1: Well | K1: MTP | M1: Content | N1: Well | O1: Trough
A2: =IF('Plate organization+'!B3="","",'Plate organization+'!B3) -> Psyn | B2: A01 | C2: =IF(A2="","",'Plate organization+'!$A$1) -> mtp_dna_stocks | E2: =IF('Plate organization+'!B15="","",'Plate organization+'!B15) -> Mastermix1 | F2: A01 | G2: =IF(E2="","",'Plate organization+'!$A$13) -> mtp_mastermix | I2: =IF('Plate organization+'!B27="","",'Plate organization+'!B27) -> Psyn | J2: A01 | K2: =IF(I2="","",'Plate organization+'!$A$25) -> mtp_source | M2: water | N2: A01 | O2: =IF(M2=0,"",M2) -> water | P2: <------------ | Q2: Tröge haben nur ein well
A3: =IF('Plate organization+'!B4="","",'Plate organization+'!B4) -> RBS | B3: B01 | C3: =IF(A3="","",'Plate organization+'!$A$1) -> mtp_dna_stocks | E3: =IF('Plate organization+'!B16="","",'Plate organization+'!B16) | F3: B01 | G3: =IF(E3="","",'Plate organization+'!$A$13) | I3: =IF('Plate organization+'!B28="","",'Plate organization+'!B28) -> RBS | J3: B01 | K3: =IF(I3="","",'Plate organization+'!$A$25) -> mtp_source | N3: B01 | O3: =IF(M3=0,"",M3)
A4: =IF('Plate organization+'!B5="","",'Plate organization+'!B5) -> aroF_S188C | B4: C01 | C4: =IF(A4="","",'Plate organization+'!$A$1) -> mtp_dna_stocks | E4: =IF('Plate organization+'!B17="","",'Plate organization+'!B17) | F4: C01 | G4: =IF(E4="","",'Plate organization+'!$A$13) | I4: =IF('Plate organization+'!B29="","",'Plate organization+'!B29) -> aroF_S188C | J4: C01 | K4: =IF(I4="","",'Plate organization+'!$A$25) -> mtp_source | N4: C01 | O4: =IF(M4=0,"",M4)
A5: =IF('Plate organization+'!B6="","",'Plate organization+'!B6) -> TrrnB | B5: D01 | C5: =IF(A5="","",'Plate organization+'!$A$1) -> mtp_dna_stocks | E5: =IF('Plate organization+'!B18="","",'Plate organization+'!B18) | F5: D01 | G5: =IF(E5="","",'Plate organization+'!$A$13) | I5: =IF('Plate organization+'!B30="","",'Plate organization+'!B30) -> TrrnB | J5: D01 | K5: =IF(I5="","",'Plate organization+'!$A$25) -> mtp_source | N5: D01 | O5: =IF(M5=0,"",M5)
A6: =IF('Plate organization+'!B7="","",'Plate organization+'!B7) -> DVK_AE | B6: E01 | C6: =IF(A6="","",'Plate organization+'!$A$1) -> mtp_dna_stocks | E6: =IF('Plate organization+'!B19="","",'Plate organization+'!B19) | F6: E01 | G6: =IF(E6="","",'Plate organization+'!$A$13) | I6: =IF('Plate organization+'!B31="","",'Plate organization+'!B31) -> DVK_AE | J6: E01 | K6: =IF(I6="","",'Plate organization+'!$A$25) -> mtp_source | N6: E01 | O6: =IF(M6=0,"",M6)
A7: =IF('Plate organization+'!B8="","",'Plate organization+'!B8) | B7: F01 | C7: =IF(A7="","",'Plate organization+'!$A$1) | E7: =IF('Plate organization+'!B20="","",'Plate organization+'!B20) | F7: F01 | G7: =IF(E7="","",'Plate organization+'!$A$13) | I7: =IF('Plate organization+'!B32="","",'Plate organization+'!B32) | J7: F01 | K7: =IF(I7="","",'Plate organization+'!$A$25) | N7: F01 | O7: =IF(M7=0,"",M7)
A8: =IF('Plate organization+'!B9="","",'Plate organization+'!B9) | B8: G01 | C8: =IF(A8="","",'Plate organization+'!$A$1) | E8: =IF('Plate organization+'!B21="","",'Plate organization+'!B21) | F8: G01 | G8: =IF(E8="","",'Plate organization+'!$A$13) | I8: =IF('Plate organization+'!B33="","",'Plate organization+'!B33) | J8: G01 | K8: =IF(I8="","",'Plate organization+'!$A$25) | N8: G01 | O8: =IF(M8=0,"",M8)
A9: =IF('Plate organization+'!B10="","",'Plate organization+'!B10) | B9: H01 | C9: =IF(A9="","",'Plate organization+'!$A$1) | E9: =IF('Plate organization+'!B22="","",'Plate organization+'!B22) | F9: H01 | G9: =IF(E9="","",'Plate organization+'!$A$13) | I9: =IF('Plate organization+'!B34="","",'Plate organization+'!B34) -> Plasmidmix1 | J9: H01 | K9: =IF(I9="","",'Plate organization+'!$A$25) -> mtp_source | N9: H01 | O9: =IF(M9=0,"",M9)
A10: =IF('Plate organization+'!C3="","",'Plate organization+'!C3) -> PH36 | B10: A02 | C10: =IF(A10="","",'Plate organization+'!$A$1) -> mtp_dna_stocks | E10: =IF('Plate organization+'!C15="","",'Plate organization+'!C15) | F10: A02 | G10: =IF(E10="","",'Plate organization+'!$A$13) | I10: =IF('Plate organization+'!C27="","",'Plate organization+'!C27) -> PH36 | J10: A02 | K10: =IF(I10="","",'Plate organization+'!$A$25) -> mtp_source
A11: =IF('Plate organization+'!C4="","",'Plate organization+'!C4) | B11: B02 | C11: =IF(A11="","",'Plate organization+'!$A$1) | E11: =IF('Plate organization+'!C16="","",'Plate organization+'!C16) | F11: B02 | G11: =IF(E11="","",'Plate organization+'!$A$13) | I11: =IF('Plate organization+'!C28="","",'Plate organization+'!C28) | J11: B02 | K11: =IF(I11="","",'Plate organization+'!$A$25)
A12: =IF('Plate organization+'!C5="","",'Plate organization+'!C5) -> aroC | B12: C02 | C12: =IF(A12="","",'Plate organization+'!$A$1) -> mtp_dna_stocks | E12: =IF('Plate organization+'!C17="","",'Plate organization+'!C17) | F12: C02 | G12: =IF(E12="","",'Plate organization+'!$A$13) | I12: =IF('Plate organization+'!C29="","",'Plate organization+'!C29) -> aroC | J12: C02 | K12: =IF(I12="","",'Plate organization+'!$A$25) -> mtp_source
A13: =IF('Plate organization+'!C6="","",'Plate organization+'!C6) | B13: D02 | C13: =IF(A13="","",'Plate organization+'!$A$1) | E13: =IF('Plate organization+'!C18="","",'Plate organization+'!C18) | F13: D02 | G13: =IF(E13="","",'Plate organization+'!$A$13) | I13: =IF('Plate organization+'!C30="","",'Plate organization+'!C30) | J13: D02 | K13: =IF(I13="","",'Plate organization+'!$A$25)
A14: =IF('Plate organization+'!C7="","",'Plate organization+'!C7) | B14: E02 | C14: =IF(A14="","",'Plate organization+'!$A$1) | E14: =IF('Plate organization+'!C19="","",'Plate organization+'!C19) | F14: E02 | G14: =IF(E14="","",'Plate organization+'!$A$13) | I14: =IF('Plate organization+'!C31="","",'Plate organization+'!C31) | J14: E02 | K14: =IF(I14="","",'Plate organization+'!$A$25)
A15: =IF('Plate organization+'!C8="","",'Plate organization+'!C8) | B15: F02 | C15: =IF(A15="","",'Plate organization+'!$A$1) | E15: =IF('Plate organization+'!C20="","",'Plate organization+'!C20) | F15: F02 | G15: =IF(E15="","",'Plate organization+'!$A$13) | I15: =IF('Plate organization+'!C32="","",'Plate organization+'!C32) | J15: F02 | K15: =IF(I15="","",'Plate organization+'!$A$25)
A16: =IF('Plate organization+'!C9="","",'Plate organization+'!C9) | B16: G02 | C16: =IF(A16="","",'Plate organization+'!$A$1) | E16: =IF('Plate organization+'!C21="","",'Plate organization+'!C21) | F16: G02 | G16: =IF(E16="","",'Plate organization+'!$A$13) | I16: =IF('Plate organization+'!C33="","",'Plate organization+'!C33) | J16: G02 | K16: =IF(I16="","",'Plate organization+'!$A$25)
A17: =IF('Plate organization+'!C10="","",'Plate organization+'!C10) | B17: H02 | C17: =IF(A17="","",'Plate organization+'!$A$1) | E17: =IF('Plate organization+'!C22="","",'Plate organization+'!C22) | F17: H02 | G17: =IF(E17="","",'Plate organization+'!$A$13) | I17: =IF('Plate organization+'!C34="","",'Plate organization+'!C34) | J17: H02 | K17: =IF(I17="","",'Plate organization+'!$A$25)
A18: =IF('Plate organization+'!D3="","",'Plate organization+'!D3) | B18: A03 | C18: =IF(A18="","",'Plate organization+'!$A$1) | E18: =IF('Plate organization+'!D15="","",'Plate organization+'!D15) | F18: A03 | G18: =IF(E18="","",'Plate organization+'!$A$13) | I18: =IF('Plate organization+'!D27="","",'Plate organization+'!D27) | J18: A03 | K18: =IF(I18="","",'Plate organization+'!$A$25)
A19: =IF('Plate organization+'!D4="","",'Plate organization+'!D4) | B19: B03 | C19: =IF(A19="","",'Plate organization+'!$A$1) | E19: =IF('Plate organization+'!D16="","",'Plate organization+'!D16) | F19: B03 | G19: =IF(E19="","",'Plate organization+'!$A$13) | I19: =IF('Plate organization+'!D28="","",'Plate organization+'!D28) | J19: B03 | K19: =IF(I19="","",'Plate organization+'!$A$25)
A20: =IF('Plate organization+'!D5="","",'Plate organization+'!D5) | B20: C03 | C20: =IF(A20="","",'Plate organization+'!$A$1) | E20: =IF('Plate organization+'!D17="","",'Plate organization+'!D17) | F20: C03 | G20: =IF(E20="","",'Plate organization+'!$A$13) | I20: =IF('Plate organization+'!D29="","",'Plate organization+'!D29) | J20: C03 | K20: =IF(I20="","",'Plate organization+'!$A$25)
A21: =IF('Plate organization+'!D6="","",'Plate organization+'!D6) | B21: D03 | C21: =IF(A21="","",'Plate organization+'!$A$1) | E21: =IF('Plate organization+'!D18="","",'Plate organization+'!D18) | F21: D03 | G21: =IF(E21="","",'Plate organization+'!$A$13) | I21: =IF('Plate organization+'!D30="","",'Plate organization+'!D30) | J21: D03 | K21: =IF(I21="","",'Plate organization+'!$A$25)
A22: =IF('Plate organization+'!D7="","",'Plate organization+'!D7) | B22: E03 | C22: =IF(A22="","",'Plate organization+'!$A$1) | E22: =IF('Plate organization+'!D19="","",'Plate organization+'!D19) | F22: E03 | G22: =IF(E22="","",'Plate organization+'!$A$13) | I22: =IF('Plate organization+'!D31="","",'Plate organization+'!D31) | J22: E03 | K22: =IF(I22="","",'Plate organization+'!$A$25)
A23: =IF('Plate organization+'!D8="","",'Plate organization+'!D8) | B23: F03 | C23: =IF(A23="","",'Plate organization+'!$A$1) | E23: =IF('Plate organization+'!D20="","",'Plate organization+'!D20) | F23: F03 | G23: =IF(E23="","",'Plate organization+'!$A$13) | I23: =IF('Plate organization+'!D32="","",'Plate organization+'!D32) | J23: F03 | K23: =IF(I23="","",'Plate organization+'!$A$25)
A24: =IF('Plate organization+'!D9="","",'Plate organization+'!D9) | B24: G03 | C24: =IF(A24="","",'Plate organization+'!$A$1) | E24: =IF('Plate organization+'!D21="","",'Plate organization+'!D21) | F24: G03 | G24: =IF(E24="","",'Plate organization+'!$A$13) | I24: =IF('Plate organization+'!D33="","",'Plate organization+'!D33) | J24: G03 | K24: =IF(I24="","",'Plate organization+'!$A$25)
A25: =IF('Plate organization+'!D10="","",'Plate organization+'!D10) | B25: H03 | C25: =IF(A25="","",'Plate organization+'!$A$1) | E25: =IF('Plate organization+'!D22="","",'Plate organization+'!D22) | F25: H03 | G25: =IF(E25="","",'Plate organization+'!$A$13) | I25: =IF('Plate organization+'!D34="","",'Plate organization+'!D34) | J25: H03 | K25: =IF(I25="","",'Plate organization+'!$A$25)
A26: =IF('Plate organization+'!E3="","",'Plate organization+'!E3) | B26: A04 | C26: =IF(A26="","",'Plate organization+'!$A$1) | E26: =IF('Plate organization+'!E15="","",'Plate organization+'!E15) | F26: A04 | G26: =IF(E26="","",'Plate organization+'!$A$13) | I26: =IF('Plate organization+'!E27="","",'Plate organization+'!E27) | J26: A04 | K26: =IF(I26="","",'Plate organization+'!$A$25)
A27: =IF('Plate organization+'!E4="","",'Plate organization+'!E4) | B27: B04 | C27: =IF(A27="","",'Plate organization+'!$A$1) | E27: =IF('Plate organization+'!E16="","",'Plate organization+'!E16) | F27: B04 | G27: =IF(E27="","",'Plate organization+'!$A$13) | I27: =IF('Plate organization+'!E28="","",'Plate organization+'!E28) | J27: B04 | K27: =IF(I27="","",'Plate organization+'!$A$25)
A28: =IF('Plate organization+'!E5="","",'Plate organization+'!E5) | B28: C04 | C28: =IF(A28="","",'Plate organization+'!$A$1) | E28: =IF('Plate organization+'!E17="","",'Plate organization+'!E17) | F28: C04 | G28: =IF(E28="","",'Plate organization+'!$A$13) | I28: =IF('Plate organization+'!E29="","",'Plate organization+'!E29) | J28: C04 | K28: =IF(I28="","",'Plate organization+'!$A$25)
A29: =IF('Plate organization+'!E6="","",'Plate organization+'!E6) | B29: D04 | C29: =IF(A29="","",'Plate organization+'!$A$1) | F29: D04 | G29: =IF(E29="","",'Plate organization+'!$A$13) | I29: =IF('Plate organization+'!E30="","",'Plate organization+'!E30) | J29: D04 | K29: =IF(I29="","",'Plate organization+'!$A$25)
A30: =IF('Plate organization+'!E7="","",'Plate organization+'!E7) | B30: E04 | C30: =IF(A30="","",'Plate organization+'!$A$1) | E30: =IF('Plate organization+'!E19="","",'Plate organization+'!E19) | F30: E04 | G30: =IF(E30="","",'Plate organization+'!$A$13) | I30: =IF('Plate organization+'!E31="","",'Plate organization+'!E31) | J30: E04 | K30: =IF(I30="","",'Plate organization+'!$A$25)
A31: =IF('Plate organization+'!E8="","",'Plate organization+'!E8) | B31: F04 | C31: =IF(A31="","",'Plate organization+'!$A$1) | E31: =IF('Plate organization+'!E20="","",'Plate organization+'!E20) | F31: F04 | G31: =IF(E31="","",'Plate organization+'!$A$13) | I31: =IF('Plate organization+'!E32="","",'Plate organization+'!E32) | J31: F04 | K31: =IF(I31="","",'Plate organization+'!$A$25)
A32: =IF('Plate organization+'!E9="","",'Plate organization+'!E9) | B32: G04 | C32: =IF(A32="","",'Plate organization+'!$A$1) | E32: =IF('Plate organization+'!E21="","",'Plate organization+'!E21) | F32: G04 | G32: =IF(E32="","",'Plate organization+'!$A$13) | I32: =IF('Plate organization+'!E33="","",'Plate organization+'!E33) | J32: G04 | K32: =IF(I32="","",'Plate organization+'!$A$25)
A33: =IF('Plate organization+'!E10="","",'Plate organization+'!E10) | B33: H04 | C33: =IF(A33="","",'Plate organization+'!$A$1) | E33: =IF('Plate organization+'!E22="","",'Plate organization+'!E22) | F33: H04 | G33: =IF(E33="","",'Plate organization+'!$A$13) | I33: =IF('Plate organization+'!E34="","",'Plate organization+'!E34) | J33: H04 | K33: =IF(I33="","",'Plate organization+'!$A$25)
A34: =IF('Plate organization+'!F3="","",'Plate organization+'!F3) | B34: A05 | C34: =IF(A34="","",'Plate organization+'!$A$1) | E34: =IF('Plate organization+'!F15="","",'Plate organization+'!F15) | F34: A05 | G34: =IF(E34="","",'Plate organization+'!$A$13) | I34: =IF('Plate organization+'!F27="","",'Plate organization+'!F27) | J34: A05 | K34: =IF(I34="","",'Plate organization+'!$A$25)
A35: =IF('Plate organization+'!F4="","",'Plate organization+'!F4) | B35: B05 | C35: =IF(A35="","",'Plate organization+'!$A$1) | E35: =IF('Plate organization+'!F16="","",'Plate organization+'!F16) | F35: B05 | G35: =IF(E35="","",'Plate organization+'!$A$13) | I35: =IF('Plate organization+'!F28="","",'Plate organization+'!F28) | J35: B05 | K35: =IF(I35="","",'Plate organization+'!$A$25)
A36: =IF('Plate organization+'!F5="","",'Plate organization+'!F5) | B36: C05 | C36: =IF(A36="","",'Plate organization+'!$A$1) | E36: =IF('Plate organization+'!F17="","",'Plate organization+'!F17) | F36: C05 | G36: =IF(E36="","",'Plate organization+'!$A$13) | I36: =IF('Plate organization+'!F29="","",'Plate organization+'!F29) | J36: C05 | K36: =IF(I36="","",'Plate organization+'!$A$25)
A37: =IF('Plate organization+'!F6="","",'Plate organization+'!F6) | B37: D05 | C37: =IF(A37="","",'Plate organization+'!$A$1) | E37: =IF('Plate organization+'!F18="","",'Plate organization+'!F18) | F37: D05 | G37: =IF(E37="","",'Plate organization+'!$A$13) | I37: =IF('Plate organization+'!F30="","",'Plate organization+'!F30) | J37: D05 | K37: =IF(I37="","",'Plate organization+'!$A$25)
A38: =IF('Plate organization+'!F7="","",'Plate organization+'!F7) | B38: E05 | C38: =IF(A38="","",'Plate organization+'!$A$1) | E38: =IF('Plate organization+'!F19="","",'Plate organization+'!F19) | F38: E05 | G38: =IF(E38="","",'Plate organization+'!$A$13) | I38: =IF('Plate organization+'!F31="","",'Plate organization+'!F31) | J38: E05 | K38: =IF(I38="","",'Plate organization+'!$A$25)
A39: =IF('Plate organization+'!F8="","",'Plate organization+'!F8) | B39: F05 | C39: =IF(A39="","",'Plate organization+'!$A$1) | E39: =IF('Plate organization+'!F20="","",'Plate organization+'!F20) | F39: F05 | G39: =IF(E39="","",'Plate organization+'!$A$13) | I39: =IF('Plate organization+'!F32="","",'Plate organization+'!F32) | J39: F05 | K39: =IF(I39="","",'Plate organization+'!$A$25)
A40: =IF('Plate organization+'!F9="","",'Plate organization+'!F9) | B40: G05 | C40: =IF(A40="","",'Plate organization+'!$A$1) | E40: =IF('Plate organization+'!F21="","",'Plate organization+'!F21) | F40: G05 | G40: =IF(E40="","",'Plate organization+'!$A$13) | I40: =IF('Plate organization+'!F33="","",'Plate organization+'!F33) | J40: G05 | K40: =IF(I40="","",'Plate organization+'!$A$25)
...

Sheet Worklist_W
A1: Well Nr. source plate | B1: Well Nr. destination plate | C1: Part | D1: Volumen | E1: Destination_plate
A2: =IF(C2="","",VLOOKUP(C2,Source_Plate!$M$2:$N$9,2,FALSE)) -> A01 | B2: =IF(C2="","",'Plan+'!K2) -> A01 | C2: =IF('DNA_dilution+'!I2="","",Source_Plate!$M$2) -> water | D2: =IF(C2="","",'DNA_dilution+'!M2-'DNA_dilution+'!L2) -> 82.350582 | E2: =Source_Plate!$E$1 -> Content
A3: =IF(C3="","",VLOOKUP(C3,Source_Plate!$M$2:$N$9,2,FALSE)) -> A01 | B3: =IF(C3="","",'Plan+'!K3) -> B01 | C3: =IF('DNA_dilution+'!I3="","",Source_Plate!$M$2) -> water | D3: =IF(C3="","",'DNA_dilution+'!M3-'DNA_dilution+'!L3) -> 90.743312 | E3: =Source_Plate!$E$1 -> Content
A4: =IF(C4="","",VLOOKUP(C4,Source_Plate!$M$2:$N$9,2,FALSE)) -> A01 | B4: =IF(C4="","",'Plan+'!K4) -> C01 | C4: =IF('DNA_dilution+'!I4="","",Source_Plate!$M$2) -> water | D4: =IF(C4="","",'DNA_dilution+'!M4-'DNA_dilution+'!L4) -> 88.931755 | E4: =Source_Plate!$E$1 -> Content
A5: =IF(C5="","",VLOOKUP(C5,Source_Plate!$M$2:$N$9,2,FALSE)) -> A01 | B5: =IF(C5="","",'Plan+'!K5) -> D01 | C5: =IF('DNA_dilution+'!I5="","",Source_Plate!$M$2) -> water | D5: =IF(C5="","",'DNA_dilution+'!M5-'DNA_dilution+'!L5) -> 77.036819 | E5: =Source_Plate!$E$1 -> Content
A6: =IF(C6="","",VLOOKUP(C6,Source_Plate!$M$2:$N$9,2,FALSE)) -> A01 | B6: =IF(C6="","",'Plan+'!K6) -> E01 | C6: =IF('DNA_dilution+'!I6="","",Source_Plate!$M$2) -> water | D6: =IF(C6="","",'DNA_dilution+'!M6-'DNA_dilution+'!L6) -> 99.793713 | E6: =Source_Plate!$E$1 -> Content
A7: =IF(C7="","",VLOOKUP(C7,Source_Plate!$M$2:$N$9,2,FALSE)) | B7: =IF(C7="","",'Plan+'!K7) | C7: =IF('DNA_dilution+'!I7="","",Source_Plate!$M$2) | D7: =IF(C7="","",'DNA_dilution+'!M7-'DNA_dilution+'!L7) | E7: =Source_Plate!$E$1 -> Content
A8: =IF(C8="","",VLOOKUP(C8,Source_Plate!$M$2:$N$9,2,FALSE)) | B8: =IF(C8="","",'Plan+'!K8) | C8: =IF('DNA_dilution+'!I8="","",Source_Plate!$M$2) | D8: =IF(C8="","",'DNA_dilution+'!M8-'DNA_dilution+'!L8) | E8: =Source_Plate!$E$1 -> Content
A9: =IF(C9="","",VLOOKUP(C9,Source_Plate!$M$2:$N$9,2,FALSE)) | B9: =IF(C9="","",'Plan+'!K9) | C9: =IF('DNA_dilution+'!I9="","",Source_Plate!$M$2) | D9: =IF(C9="","",'DNA_dilution+'!M9-'DNA_dilution+'!L9) | E9: =Source_Plate!$E$1 -> Content
A10: =IF(C10="","",VLOOKUP(C10,Source_Plate!$M$2:$N$9,2,FALSE)) -> A01 | B10: =IF(C10="","",'Plan+'!K10) -> A02 | C10: =IF('DNA_dilution+'!I10="","",Source_Plate!$M$2) -> water | D10: =IF(C10="","",'DNA_dilution+'!M10-'DNA_dilution+'!L10) -> 84.212859 | E10: =Source_Plate!$E$1 -> Content
A11: =IF(C11="","",VLOOKUP(C11,Source_Plate!$M$2:$N$9,2,FALSE)) | B11: =IF(C11="","",'Plan+'!K11) | C11: =IF('DNA_dilution+'!I11="","",Source_Plate!$M$2) | D11: =IF(C11="","",'DNA_dilution+'!M11-'DNA_dilution+'!L11) | E11: =Source_Plate!$E$1 -> Content
A12: =IF(C12="","",VLOOKUP(C12,Source_Plate!$M$2:$N$9,2,FALSE)) -> A01 | B12: =IF(C12="","",'Plan+'!K12) -> C02 | C12: =IF('DNA_dilution+'!I12="","",Source_Plate!$M$2) -> water | D12: =IF(C12="","",'DNA_dilution+'!M12-'DNA_dilution+'!L12) -> 93.320698 | E12: =Source_Plate!$E$1 -> Content
A13: =IF(C13="","",VLOOKUP(C13,Source_Plate!$M$2:$N$9,2,FALSE)) | B13: =IF(C13="","",'Plan+'!K13) | C13: =IF('DNA_dilution+'!I13="","",Source_Plate!$M$2) | D13: =IF(C13="","",'DNA_dilution+'!M13-'DNA_dilution+'!L13) | E13: =Source_Plate!$E$1 -> Content
... A97: =IF(C97="","",VLOOKUP(C97,Source_Plate!$M$2:$N$9,2,FALSE)) | B97: =IF(C97="","",'Plan+'!K97) | C97: =IF('DNA_dilution+'!I97="","",Source_Plate!$M$2) | D97: =IF(C97="","",'DNA_dilution+'!M97-'DNA_dilution+'!L97) | E97: =Source_Plate!$E$1 -> Content
A98: =IF(C98="","",VLOOKUP(C98,Source_Plate!$M$2:$N$9,2,FALSE)) | B98: =IF(C98="","",'Plan+'!#REF!) | C98: =IF('DNA_dilution+'!I98="","",Source_Plate!$M$2) | D98: =IF(C98="","",'DNA_dilution+'!M98-'DNA_dilution+'!L98) | E98: =Source_Plate!$E$1 -> Content
A99: =IF(C99="","",VLOOKUP(C99,Source_Plate!$M$2:$N$9,2,FALSE)) | B99: =IF(C99="","",'Plan+'!#REF!) | C99: =IF('DNA_dilution+'!I99="","",Source_Plate!$M$2) | D99: =IF(C99="","",'DNA_dilution+'!M99-'DNA_dilution+'!L99) | E99: =Source_Plate!$E$1 -> Content
A100: =IF(C100="","",VLOOKUP(C100,Source_Plate!$M$2:$N$9,2,FALSE)) | B100: =IF(C100="","",'Plan+'!#REF!) | C100: =IF('DNA_dilution+'!I100="","",Source_Plate!$M$2) | D100: =IF(C100="","",'DNA_dilution+'!M100-'DNA_dilution+'!L100) | E100: =Source_Plate!$E$1 -> Content
A101: =IF(C101="","",VLOOKUP(C101,Source_Plate!$M$2:$N$9,2,FALSE)) | B101: =IF(C101="","",'Plan+'!#REF!) | C101: =IF('DNA_dilution+'!I101="","",Source_Plate!$M$2) | D101: =IF(C101="","",'DNA_dilution+'!M101-'DNA_dilution+'!L101) | E101: =Source_Plate!$E$1 -> Content
A102: =IF(C102="","",VLOOKUP(C102,Source_Plate!$M$2:$N$9,2,FALSE)) | B102: =IF(C102="","",'Plan+'!#REF!) | C102: =IF('DNA_dilution+'!I102="","",Source_Plate!$M$2) | D102: =IF(C102="","",'DNA_dilution+'!M102-'DNA_dilution+'!L102) | E102: =Source_Plate!$E$1 -> Content
A103: =IF(C103="","",VLOOKUP(C103,Source_Plate!$M$2:$N$9,2,FALSE)) | B103: =IF(C103="","",'Plan+'!#REF!) | C103: =IF('DNA_dilution+'!I103="","",Source_Plate!$M$2) | D103: =IF(C103="","",'DNA_dilution+'!M103-'DNA_dilution+'!L103) | E103: =Source_Plate!$E$1 -> Content
A104: =IF(C104="","",VLOOKUP(C104,Source_Plate!$M$2:$N$9,2,FALSE)) | B104: =IF(C104="","",'Plan+'!#REF!) | C104: =IF('DNA_dilution+'!I104="","",Source_Plate!$M$2) | D104: =IF(C104="","",'DNA_dilution+'!M104-'DNA_dilution+'!L104) | E104: =Source_Plate!$E$1 -> Content
A105: =IF(C105="","",VLOOKUP(C105,Source_Plate!$M$2:$N$9,2,FALSE)) | B105: =IF(C105="","",'Plan+'!#REF!) | C105: =IF('DNA_dilution+'!I105="","",Source_Plate!$M$2) | D105: =IF(C105="","",'DNA_dilution+'!M105-'DNA_dilution+'!L105) | E105: =Source_Plate!$E$1 -> Content
A106: =IF(C106="","",VLOOKUP(C106,Source_Plate!$M$2:$N$9,2,FALSE)) | B106: =IF(C106="","",'Plan+'!#REF!) | C106: =IF('DNA_dilution+'!I106="","",Source_Plate!$M$2) | D106: =IF(C106="","",'DNA_dilution+'!M106-'DNA_dilution+'!L106) | E106: =Source_Plate!$E$1 -> Content
A107: =IF(C107="","",VLOOKUP(C107,Source_Plate!$M$2:$N$9,2,FALSE)) | B107: =IF(C107="","",'Plan+'!#REF!) | C107: =IF('DNA_dilution+'!I107="","",Source_Plate!$M$2) | D107: =IF(C107="","",'DNA_dilution+'!M107-'DNA_dilution+'!L107) | E107: =Source_Plate!$E$1 -> Content
A108: =IF(C108="","",VLOOKUP(C108,Source_Plate!$M$2:$N$9,2,FALSE)) | B108: =IF(C108="","",'Plan+'!#REF!) | C108: =IF('DNA_dilution+'!I108="","",Source_Plate!$M$2) | D108: =IF(C108="","",'DNA_dilution+'!M108-'DNA_dilution+'!L108) | E108: =Source_Plate!$E$1 -> Content
A109: =IF(C109="","",VLOOKUP(C109,Source_Plate!$M$2:$N$9,2,FALSE)) | B109: =IF(C109="","",'Plan+'!#REF!) | C109: =IF('DNA_dilution+'!I109="","",Source_Plate!$M$2) | D109: =IF(C109="","",'DNA_dilution+'!M109-'DNA_dilution+'!L109) | E109: =Source_Plate!$E$1 -> Content
... A188: =IF(C188="","",VLOOKUP(C188,Source_Plate!$M$2:$N$9,2,FALSE)) | B188: =IF(C188="","",'Plan+'!#REF!) | C188: =IF('DNA_dilution+'!I188="","",Source_Plate!$M$2) | D188: =IF(C188="","",'DNA_dilution+'!M188-'DNA_dilution+'!L188) | E188: =Source_Plate!$E$1 -> Content
B189: =COUNTA(B2:B188) -> 187

Sheet Worklist_DNA
A1: Well Nr. source plate | B1: Well Nr. destination plate | C1: Part | D1: Volumen | E1: Destination_plate
A2: =IF(C2="","",VLOOKUP(C2,Source_Plate!$A$2:$B$97,2,FALSE)) -> A01 | B2: =IF(C2="","",'Plan+'!K2) -> A01 | C2: =IF('DNA_dilution+'!I2="","",'DNA_dilution+'!H2) -> Psyn | D2: =IF(C2="","",'DNA_dilution+'!L2) -> 17.649418 | E2: =Source_Plate!$E$1 -> Content
A3: =IF(C3="","",VLOOKUP(C3,Source_Plate!$A$2:$B$97,2,FALSE)) -> B01 | B3: =IF(C3="","",'Plan+'!K3) -> B01 | C3: =IF('DNA_dilution+'!I3="","",'DNA_dilution+'!H3) -> RBS | D3: =IF(C3="","",'DNA_dilution+'!L3) -> 9.2566878 | E3: =Source_Plate!$E$1 -> Content
A4: =IF(C4="","",VLOOKUP(C4,Source_Plate!$A$2:$B$97,2,FALSE)) -> C01 | B4: =IF(C4="","",'Plan+'!K4) -> C01 | C4: =IF('DNA_dilution+'!I4="","",'DNA_dilution+'!H4) -> aroF_S188C | D4: =IF(C4="","",'DNA_dilution+'!L4) -> 11.068245 | E4: =Source_Plate!$E$1 -> Content
A5: =IF(C5="","",VLOOKUP(C5,Source_Plate!$A$2:$B$97,2,FALSE)) -> D01 | B5: =IF(C5="","",'Plan+'!K5) -> D01 | C5: =IF('DNA_dilution+'!I5="","",'DNA_dilution+'!H5) -> TrrnB | D5: =IF(C5="","",'DNA_dilution+'!L5) -> 22.963181 | E5: =Source_Plate!$E$1 -> Content
A6: =IF(C6="","",VLOOKUP(C6,Source_Plate!$A$2:$B$97,2,FALSE)) -> E01 | B6: =IF(C6="","",'Plan+'!K6) -> E01 | C6: =IF('DNA_dilution+'!I6="","",'DNA_dilution+'!H6) -> DVK_AE | D6: =IF(C6="","",'DNA_dilution+'!L6) -> 0.206287 | E6: =Source_Plate!$E$1 -> Content
A7: =IF(C7="","",VLOOKUP(C7,Source_Plate!$A$2:$B$97,2,FALSE)) | B7: =IF(C7="","",'Plan+'!K7) | C7: =IF('DNA_dilution+'!I7="","",'DNA_dilution+'!H7) | D7: =IF(C7="","",'DNA_dilution+'!L7) | E7: =Source_Plate!$E$1 -> Content
A8: =IF(C8="","",VLOOKUP(C8,Source_Plate!$A$2:$B$97,2,FALSE)) | B8: =IF(C8="","",'Plan+'!K8) | C8: =IF('DNA_dilution+'!I8="","",'DNA_dilution+'!H8) | D8: =IF(C8="","",'DNA_dilution+'!L8) | E8: =Source_Plate!$E$1 -> Content
A9: =IF(C9="","",VLOOKUP(C9,Source_Plate!$A$2:$B$97,2,FALSE)) | B9: =IF(C9="","",'Plan+'!K9) | C9: =IF('DNA_dilution+'!I9="","",'DNA_dilution+'!H9) | D9: =IF(C9="","",'DNA_dilution+'!L9) | E9: =Source_Plate!$E$1 -> Content
A10: =IF(C10="","",VLOOKUP(C10,Source_Plate!$A$2:$B$97,2,FALSE)) -> A02 | B10: =IF(C10="","",'Plan+'!K10) -> A02 | C10: =IF('DNA_dilution+'!I10="","",'DNA_dilution+'!H10) -> PH36 | D10: =IF(C10="","",'DNA_dilution+'!L10) -> 15.787141 | E10: =Source_Plate!$E$1 -> Content
A11: =IF(C11="","",VLOOKUP(C11,Source_Plate!$A$2:$B$97,2,FALSE)) | B11: =IF(C11="","",'Plan+'!K11) | C11: =IF('DNA_dilution+'!I11="","",'DNA_dilution+'!H11) | D11: =IF(C11="","",'DNA_dilution+'!L11) | E11: =Source_Plate!$E$1 -> Content
A12: =IF(C12="","",VLOOKUP(C12,Source_Plate!$A$2:$B$97,2,FALSE)) -> C02 | B12: =IF(C12="","",'Plan+'!K12) -> C02 | C12: =IF('DNA_dilution+'!I12="","",'DNA_dilution+'!H12) -> aroC | D12: =IF(C12="","",'DNA_dilution+'!L12) -> 6.6793016 | E12: =Source_Plate!$E$1 -> Content
A13: =IF(C13="","",VLOOKUP(C13,Source_Plate!$A$2:$B$97,2,FALSE)) | B13: =IF(C13="","",'Plan+'!K13) | C13: =IF('DNA_dilution+'!I13="","",'DNA_dilution+'!H13) | D13: =IF(C13="","",'DNA_dilution+'!L13) | E13: =Source_Plate!$E$1 -> Content
... A97: =IF(C97="","",VLOOKUP(C97,Source_Plate!$A$2:$B$97,2,FALSE)) | B97: =IF(C97="","",'Plan+'!K97) | C97: =IF('DNA_dilution+'!I97="","",'DNA_dilution+'!H97) | D97: =IF(C97="","",'DNA_dilution+'!L97) | E97: =Source_Plate!$E$1 -> Content
A98: =IF(C98="","",VLOOKUP(C98,Source_Plate!$A$2:$B$97,2,FALSE)) | B98: =IF(C98="","",'Plan+'!#REF!) | C98: =IF('DNA_dilution+'!I98="","",'DNA_dilution+'!H98) | D98: =IF(C98="","",'DNA_dilution+'!L98) | E98: =Source_Plate!$E$1 -> Content
A99: =IF(C99="","",VLOOKUP(C99,Source_Plate!$A$2:$B$97,2,FALSE)) | B99: =IF(C99="","",'Plan+'!#REF!) | C99: =IF('DNA_dilution+'!I99="","",'DNA_dilution+'!H99) | D99: =IF(C99="","",'DNA_dilution+'!L99) | E99: =Source_Plate!$E$1 -> Content
A100: =IF(C100="","",VLOOKUP(C100,Source_Plate!$A$2:$B$97,2,FALSE)) | B100: =IF(C100="","",'Plan+'!#REF!) | C100: =IF('DNA_dilution+'!I100="","",'DNA_dilution+'!H100) | D100: =IF(C100="","",'DNA_dilution+'!L100) | E100: =Source_Plate!$E$1 -> Content
A101: =IF(C101="","",VLOOKUP(C101,Source_Plate!$A$2:$B$97,2,FALSE)) | B101: =IF(C101="","",'Plan+'!#REF!) | C101: =IF('DNA_dilution+'!I101="","",'DNA_dilution+'!H101) | D101: =IF(C101="","",'DNA_dilution+'!L101) | E101: =Source_Plate!$E$1 -> Content
A102: =IF(C102="","",VLOOKUP(C102,Source_Plate!$A$2:$B$97,2,FALSE)) | B102: =IF(C102="","",'Plan+'!#REF!) | C102: =IF('DNA_dilution+'!I102="","",'DNA_dilution+'!H102) | D102: =IF(C102="","",'DNA_dilution+'!L102) | E102: =Source_Plate!$E$1 -> Content
A103: =IF(C103="","",VLOOKUP(C103,Source_Plate!$A$2:$B$97,2,FALSE)) | B103: =IF(C103="","",'Plan+'!#REF!) | C103: =IF('DNA_dilution+'!I103="","",'DNA_dilution+'!H103) | D103: =IF(C103="","",'DNA_dilution+'!L103) | E103: =Source_Plate!$E$1 -> Content
A104: =IF(C104="","",VLOOKUP(C104,Source_Plate!$A$2:$B$97,2,FALSE)) | B104: =IF(C104="","",'Plan+'!#REF!) | C104: =IF('DNA_dilution+'!I104="","",'DNA_dilution+'!H104) | D104: =IF(C104="","",'DNA_dilution+'!L104) | E104: =Source_Plate!$E$1 -> Content
A105: =IF(C105="","",VLOOKUP(C105,Source_Plate!$A$2:$B$97,2,FALSE)) | B105: =IF(C105="","",'Plan+'!#REF!) | C105: =IF('DNA_dilution+'!I105="","",'DNA_dilution+'!H105) | D105: =IF(C105="","",'DNA_dilution+'!L105) | E105: =Source_Plate!$E$1 -> Content
A106: =IF(C106="","",VLOOKUP(C106,Source_Plate!$A$2:$B$97,2,FALSE)) | B106: =IF(C106="","",'Plan+'!#REF!) | C106: =IF('DNA_dilution+'!I106="","",'DNA_dilution+'!H106) | D106: =IF(C106="","",'DNA_dilution+'!L106) | E106: =Source_Plate!$E$1 -> Content
A107: =IF(C107="","",VLOOKUP(C107,Source_Plate!$A$2:$B$97,2,FALSE)) | B107: =IF(C107="","",'Plan+'!#REF!) | C107: =IF('DNA_dilution+'!I107="","",'DNA_dilution+'!H107) | D107: =IF(C107="","",'DNA_dilution+'!L107) | E107: =Source_Plate!$E$1 -> Content
A108: =IF(C108="","",VLOOKUP(C108,Source_Plate!$A$2:$B$97,2,FALSE)) | B108: =IF(C108="","",'Plan+'!#REF!) | C108: =IF('DNA_dilution+'!I108="","",'DNA_dilution+'!H108) | D108: =IF(C108="","",'DNA_dilution+'!L108) | E108: =Source_Plate!$E$1 -> Content
A109: =IF(C109="","",VLOOKUP(C109,Source_Plate!$A$2:$B$97,2,FALSE)) | B109: =IF(C109="","",'Plan+'!#REF!) | C109: =IF('DNA_dilution+'!I109="","",'DNA_dilution+'!H109) | D109: =IF(C109="","",'DNA_dilution+'!L109) | E109: =Source_Plate!$E$1 -> Content
... A188: =IF(C188="","",VLOOKUP(C188,Source_Plate!$A$2:$B$97,2,FALSE)) | B188: =IF(C188="","",'Plan+'!#REF!) | C188: =IF('DNA_dilution+'!I188="","",'DNA_dilution+'!H188) | D188: =IF(C188="","",'DNA_dilution+'!L188) | E188: =Source_Plate!$E$1 -> Content
B189: =COUNTA(B2:B188) -> 187

Sheet Worklist_PM_parts
A1: Well Nr. source plate | B1: Well Nr. destination plate | C1: Part | D1: Volumen | E1: Destination_plate
A2: =IF(C2="","",VLOOKUP(C2,Source_Plate!$I$2:$J$97,2,FALSE)) | B2: =IF(C2="","",'PM_info+'!B2) | C2: =IF('PM_info+'!D2="","",'PM_info+'!D2) | D2: =IF(C2="","",'Plate organization+'!$B$43) | E2: mtp_source
A3: =IF(C3="","",VLOOKUP(C3,Source_Plate!$I$2:$J$97,2,FALSE)) | B3: =IF(C3="","",'PM_info+'!B3) | C3: =IF('PM_info+'!D3="","",'PM_info+'!D3) | D3: =IF(C3="","",'Plate organization+'!$B$43) | E3: mtp_source
A4: =IF(C4="","",VLOOKUP(C4,Source_Plate!$I$2:$J$97,2,FALSE)) | B4: =IF(C4="","",'PM_info+'!B4) | C4: =IF('PM_info+'!D4="","",'PM_info+'!D4) | D4: =IF(C4="","",'Plate organization+'!$B$43) | E4: mtp_source
A5: =IF(C5="","",VLOOKUP(C5,Source_Plate!$I$2:$J$97,2,FALSE)) | B5: =IF(C5="","",'PM_info+'!B5) | C5: =IF('PM_info+'!D5="","",'PM_info+'!D5) | D5: =IF(C5="","",'Plate organization+'!$B$43) | E5: mtp_source
A6: =IF(C6="","",VLOOKUP(C6,Source_Plate!$I$2:$J$97,2,FALSE)) | B6: =IF(C6="","",'PM_info+'!B6) | C6: =IF('PM_info+'!D6="","",'PM_info+'!D6) | D6: =IF(C6="","",'Plate organization+'!$B$43) | E6: mtp_source
A7: =IF(C7="","",VLOOKUP(C7,Source_Plate!$I$2:$J$97,2,FALSE)) | B7: =IF(C7="","",'PM_info+'!B7) | C7: =IF('PM_info+'!D7="","",'PM_info+'!D7) | D7: =IF(C7="","",'Plate organization+'!$B$43) | E7: mtp_source
A8: =IF(C8="","",VLOOKUP(C8,Source_Plate!$I$2:$J$97,2,FALSE)) | B8: =IF(C8="","",'PM_info+'!B8) | C8: =IF('PM_info+'!D8="","",'PM_info+'!D8) | D8: =IF(C8="","",'Plate organization+'!$B$43) | E8: mtp_source
A9: =IF(C9="","",VLOOKUP(C9,Source_Plate!$I$2:$J$97,2,FALSE)) -> B01 | B9: =IF(C9="","",'PM_info+'!B9) -> H01 | C9: =IF('PM_info+'!D9="","",'PM_info+'!D9) -> RBS | D9: =IF(C9="","",'Plate organization+'!$B$43) -> 15 | E9: mtp_source
A10: =IF(C10="","",VLOOKUP(C10,Source_Plate!$I$2:$J$97,2,FALSE)) | B10: =IF(C10="","",'PM_info+'!B10) | C10: =IF('PM_info+'!D10="","",'PM_info+'!D10) | D10: =IF(C10="","",'Plate organization+'!$B$43) | E10: mtp_source
A11: =IF(C11="","",VLOOKUP(C11,Source_Plate!$I$2:$J$97,2,FALSE)) | B11: =IF(C11="","",'PM_info+'!B11) | C11: =IF('PM_info+'!D11="","",'PM_info+'!D11) | D11: =IF(C11="","",'Plate organization+'!$B$43) | E11: mtp_source
A12: =IF(C12="","",VLOOKUP(C12,Source_Plate!$I$2:$J$97,2,FALSE)) | B12: =IF(C12="","",'PM_info+'!B12) | C12: =IF('PM_info+'!D12="","",'PM_info+'!D12) | D12: =IF(C12="","",'Plate organization+'!$B$43) | E12: mtp_source
A13: =IF(C13="","",VLOOKUP(C13,Source_Plate!$I$2:$J$97,2,FALSE)) | B13: =IF(C13="","",'PM_info+'!B13) | C13: =IF('PM_info+'!D13="","",'PM_info+'!D13) | D13: =IF(C13="","",'Plate organization+'!$B$43) | E13: mtp_source
... A97: =IF(C97="","",VLOOKUP(C97,Source_Plate!$I$2:$J$97,2,FALSE)) | B97: =IF(C97="","",'PM_info+'!B97) | C97: =IF('PM_info+'!D97="","",'PM_info+'!D97) | D97: =IF(C97="","",'Plate organization+'!$B$43) | E97: mtp_source
A98: =IF(C98="","",VLOOKUP(C98,Source_Plate!$I$2:$J$97,2,FALSE)) | B98: =IF(C98="","",'PM_info+'!B2) | C98: =IF('PM_info+'!E2="","",'PM_info+'!E2) | D98: =IF(C98="","",'Plate organization+'!$B$43) | E98: mtp_source
A99: =IF(C99="","",VLOOKUP(C99,Source_Plate!$I$2:$J$97,2,FALSE)) | B99: =IF(C99="","",'PM_info+'!B3) | C99: =IF('PM_info+'!E3="","",'PM_info+'!E3) | D99: =IF(C99="","",'Plate organization+'!$B$43) | E99: mtp_source
A100: =IF(C100="","",VLOOKUP(C100,Source_Plate!$I$2:$J$97,2,FALSE)) | B100: =IF(C100="","",'PM_info+'!B4) | C100: =IF('PM_info+'!E4="","",'PM_info+'!E4) | D100: =IF(C100="","",'Plate organization+'!$B$43) | E100: mtp_source
A101: =IF(C101="","",VLOOKUP(C101,Source_Plate!$I$2:$J$97,2,FALSE)) | B101: =IF(C101="","",'PM_info+'!B5) | C101: =IF('PM_info+'!E5="","",'PM_info+'!E5) | D101: =IF(C101="","",'Plate organization+'!$B$43) | E101: mtp_source
A102: =IF(C102="","",VLOOKUP(C102,Source_Plate!$I$2:$J$97,2,FALSE)) | B102: =IF(C102="","",'PM_info+'!B6) | C102: =IF('PM_info+'!E6="","",'PM_info+'!E6) | D102: =IF(C102="","",'Plate organization+'!$B$43) | E102: mtp_source
A103: =IF(C103="","",VLOOKUP(C103,Source_Plate!$I$2:$J$97,2,FALSE)) | B103: =IF(C103="","",'PM_info+'!B7) | C103: =IF('PM_info+'!E7="","",'PM_info+'!E7) | D103: =IF(C103="","",'Plate organization+'!$B$43) | E103: mtp_source
A104: =IF(C104="","",VLOOKUP(C104,Source_Plate!$I$2:$J$97,2,FALSE)) | B104: =IF(C104="","",'PM_info+'!B8) | C104: =IF('PM_info+'!E8="","",'PM_info+'!E8) | D104: =IF(C104="","",'Plate organization+'!$B$43) | E104: mtp_source
A105: =IF(C105="","",VLOOKUP(C105,Source_Plate!$I$2:$J$97,2,FALSE)) -> D01 | B105: =IF(C105="","",'PM_info+'!B9) -> H01 | C105: =IF('PM_info+'!E9="","",'PM_info+'!E9) -> TrrnB | D105: =IF(C105="","",'Plate organization+'!$B$43) -> 15 | E105: mtp_source
A106: =IF(C106="","",VLOOKUP(C106,Source_Plate!$I$2:$J$97,2,FALSE)) | B106: =IF(C106="","",'PM_info+'!B10) | C106: =IF('PM_info+'!E10="","",'PM_info+'!E10) | D106: =IF(C106="","",'Plate organization+'!$B$43) | E106: mtp_source
A107: =IF(C107="","",VLOOKUP(C107,Source_Plate!$I$2:$J$97,2,FALSE)) | B107: =IF(C107="","",'PM_info+'!B11) | C107: =IF('PM_info+'!E11="","",'PM_info+'!E11) | D107: =IF(C107="","",'Plate organization+'!$B$43) | E107: mtp_source
A108: =IF(C108="","",VLOOKUP(C108,Source_Plate!$I$2:$J$97,2,FALSE)) | B108: =IF(C108="","",'PM_info+'!B12) | C108: =IF('PM_info+'!E12="","",'PM_info+'!E12) | D108: =IF(C108="","",'Plate organization+'!$B$43) | E108: mtp_source
A109: =IF(C109="","",VLOOKUP(C109,Source_Plate!$I$2:$J$97,2,FALSE)) | B109: =IF(C109="","",'PM_info+'!B13) | C109: =IF('PM_info+'!E13="","",'PM_info+'!E13) | D109: =IF(C109="","",'Plate organization+'!$B$43) | E109: mtp_source
... A193: =IF(C193="","",VLOOKUP(C193,Source_Plate!$I$2:$J$97,2,FALSE)) | B193: =IF(C193="","",'PM_info+'!B97) | C193: =IF('PM_info+'!E97="","",'PM_info+'!E97) | D193: =IF(C193="","",'Plate organization+'!$B$43) | E193: mtp_source
A194: =IF(C194="","",VLOOKUP(C194,Source_Plate!$I$2:$J$97,2,FALSE)) | B194: =IF(C194="","",'PM_info+'!B2) | C194: =IF('PM_info+'!F2="","",'PM_info+'!F2) | D194: =IF(C194="","",'Plate organization+'!$B$43) | E194: mtp_source
A195: =IF(C195="","",VLOOKUP(C195,Source_Plate!$I$2:$J$97,2,FALSE)) | B195: =IF(C195="","",'PM_info+'!B3) | C195: =IF('PM_info+'!F3="","",'PM_info+'!F3) | D195: =IF(C195="","",'Plate organization+'!$B$43) | E195: mtp_source
A196: =IF(C196="","",VLOOKUP(C196,Source_Plate!$I$2:$J$97,2,FALSE)) | B196: =IF(C196="","",'PM_info+'!B4) | C196: =IF('PM_info+'!F4="","",'PM_info+'!F4) | D196: =IF(C196="","",'Plate organization+'!$B$43) | E196: mtp_source
A197: =IF(C197="","",VLOOKUP(C197,Source_Plate!$I$2:$J$97,2,FALSE)) | B197: =IF(C197="","",'PM_info+'!B5) | C197: =IF('PM_info+'!F5="","",'PM_info+'!F5) | D197: =IF(C197="","",'Plate organization+'!$B$43) | E197: mtp_source
A198: =IF(C198="","",VLOOKUP(C198,Source_Plate!$I$2:$J$97,2,FALSE)) | B198: =IF(C198="","",'PM_info+'!B6) | C198: =IF('PM_info+'!F6="","",'PM_info+'!F6) | D198: =IF(C198="","",'Plate organization+'!$B$43) | E198: mtp_source
A199: =IF(C199="","",VLOOKUP(C199,Source_Plate!$I$2:$J$97,2,FALSE)) | B199: =IF(C199="","",'PM_info+'!B7) | C199: =IF('PM_info+'!F7="","",'PM_info+'!F7) | D199: =IF(C199="","",'Plate organization+'!$B$43) | E199: mtp_source
A200: =IF(C200="","",VLOOKUP(C200,Source_Plate!$I$2:$J$97,2,FALSE)) | B200: =IF(C200="","",'PM_info+'!B8) | C200: =IF('PM_info+'!F8="","",'PM_info+'!F8) | D200: =IF(C200="","",'Plate organization+'!$B$43) | E200: mtp_source
A201: =IF(C201="","",VLOOKUP(C201,Source_Plate!$I$2:$J$97,2,FALSE)) -> E01 | B201: =IF(C201="","",'PM_info+'!B9) -> H01 | C201: =IF('PM_info+'!F9="","",'PM_info+'!F9) -> DVK_AE | D201: =IF(C201="","",'Plate organization+'!$B$43) -> 15 | E201: mtp_source
A202: =IF(C202="","",VLOOKUP(C202,Source_Plate!$I$2:$J$97,2,FALSE)) | B202: =IF(C202="","",'PM_info+'!B10) | C202: =IF('PM_info+'!F10="","",'PM_info+'!F10) | D202: =IF(C202="","",'Plate organization+'!$B$43) | E202: mtp_source
A203: =IF(C203="","",VLOOKUP(C203,Source_Plate!$I$2:$J$97,2,FALSE)) | B203: =IF(C203="","",'PM_info+'!B11) | C203: =IF('PM_info+'!F11="","",'PM_info+'!F11) | D203: =IF(C203="","",'Plate organization+'!$B$43) | E203: mtp_source
A204: =IF(C204="","",VLOOKUP(C204,Source_Plate!$I$2:$J$97,2,FALSE)) | B204: =IF(C204="","",'PM_info+'!B12) | C204: =IF('PM_info+'!F12="","",'PM_info+'!F12) | D204: =IF(C204="","",'Plate organization+'!$B$43) | E204: mtp_source
A205: =IF(C205="","",VLOOKUP(C205,Source_Plate!$I$2:$J$97,2,FALSE)) | B205: =IF(C205="","",'PM_info+'!B13) | C205: =IF('PM_info+'!F13="","",'PM_info+'!F13) | D205: =IF(C205="","",'Plate organization+'!$B$43) | E205: mtp_source
... A289: =IF(C289="","",VLOOKUP(C289,Source_Plate!$I$2:$J$97,2,FALSE)) | B289: =IF(C289="","",'PM_info+'!B97) | C289: =IF('PM_info+'!F97="","",'PM_info+'!F97) | D289: =IF(C289="","",'Plate organization+'!$B$43) | E289: mtp_source
...

Sheet Worklist_PM
A1: Well Nr. source plate | B1: Well Nr. destination plate | C1: Part | D1: Volumen | E1: Destination_plate
A2: =IF(C2="", "", IF(ISERROR(VLOOKUP(C2,Source_Plate!$E$2:$F$97,2,FALSE)), IF(ISERROR(VLOOKUP(C2,Source_Plate!$I$2:$J$97,2,FALSE)), "", VLOOKUP(C2,Source_Plate!$I$2:$J$97,2,FALSE) ), VLOOKUP(C2,Source_Plate!$E$2:$F$97,2,FALSE) ) ) -> H01 | B2: =IF(C2="","",'Plan+'!K2) -> A01 | C2: =IF('Plan+'!I2="","",'Plan+'!I2) -> Plasmidmix1 | D2: =IF(C2="","",'Plate organization+'!$B$46) -> 4 | E2: ='Plan+'!L2 -> Destination_Plate_1
A3: =IF(C3="", "", IF(ISERROR(VLOOKUP(C3,Source_Plate!$E$2:$F$97,2,FALSE)), IF(ISERROR(VLOOKUP(C3,Source_Plate!$I$2:$J$97,2,FALSE)), "", VLOOKUP(C3,Source_Plate!$I$2:$J$97,2,FALSE) ), VLOOKUP(C3,Source_Plate!$E$2:$F$97,2,FALSE) ) ) -> H01 | B3: =IF(C3="","",'Plan+'!K3) -> B01 | C3: =IF('Plan+'!I3="","",'Plan+'!I3) -> Plasmidmix1 | D3: =IF(C3="","",'Plate organization+'!$B$46) -> 4 | E3: ='Plan+'!L3 -> Destination_Plate_1
A4: =IF(C4="", "", IF(ISERROR(VLOOKUP(C4,Source_Plate!$E$2:$F$97,2,FALSE)), IF(ISERROR(VLOOKUP(C4,Source_Plate!$I$2:$J$97,2,FALSE)), "", VLOOKUP(C4,Source_Plate!$I$2:$J$97,2,FALSE) ), VLOOKUP(C4,Source_Plate!$E$2:$F$97,2,FALSE) ) ) -> H01 | B4: =IF(C4="","",'Plan+'!K4) -> C01 | C4: =IF('Plan+'!I4="","",'Plan+'!I4) -> Plasmidmix1 | D4: =IF(C4="","",'Plate organization+'!$B$46) -> 4 | E4: ='Plan+'!L4 -> Destination_Plate_1
A5: =IF(C5="", "", IF(ISERROR(VLOOKUP(C5,Source_Plate!$E$2:$F$97,2,FALSE)), IF(ISERROR(VLOOKUP(C5,Source_Plate!$I$2:$J$97,2,FALSE)), "", VLOOKUP(C5,Source_Plate!$I$2:$J$97,2,FALSE) ), VLOOKUP(C5,Source_Plate!$E$2:$F$97,2,FALSE) ) ) -> H01 | B5: =IF(C5="","",'Plan+'!K5) -> D01 | C5: =IF('Plan+'!I5="","",'Plan+'!I5) -> Plasmidmix1 | D5: =IF(C5="","",'Plate organization+'!$B$46) -> 4 | E5: ='Plan+'!L5 -> Destination_Plate_1
A6: =IF(C6="", "", IF(ISERROR(VLOOKUP(C6,Source_Plate!$E$2:$F$97,2,FALSE)), IF(ISERROR(VLOOKUP(C6,Source_Plate!$I$2:$J$97,2,FALSE)), "", VLOOKUP(C6,Source_Plate!$I$2:$J$97,2,FALSE) ), VLOOKUP(C6,Source_Plate!$E$2:$F$97,2,FALSE) ) ) | B6: =IF(C6="","",'Plan+'!K6) | C6: =IF('Plan+'!I6="","",'Plan+'!I6) | D6: =IF(C6="","",'Plate organization+'!$B$46) | E6: ='Plan+'!L6 -> Destination_Plate_1
A7: =IF(C7="", "", IF(ISERROR(VLOOKUP(C7,Source_Plate!$E$2:$F$97,2,FALSE)), IF(ISERROR(VLOOKUP(C7,Source_Plate!$I$2:$J$97,2,FALSE)), "", VLOOKUP(C7,Source_Plate!$I$2:$J$97,2,FALSE) ), VLOOKUP(C7,Source_Plate!$E$2:$F$97,2,FALSE) ) ) | B7: =IF(C7="","",'Plan+'!K7) | C7: =IF('Plan+'!I7="","",'Plan+'!I7) | D7: =IF(C7="","",'Plate organization+'!$B$46) | E7: ='Plan+'!L7 -> Destination_Plate_1
A8: =IF(C8="", "", IF(ISERROR(VLOOKUP(C8,Source_Plate!$E$2:$F$97,2,FALSE)), IF(ISERROR(VLOOKUP(C8,Source_Plate!$I$2:$J$97,2,FALSE)), "", VLOOKUP(C8,Source_Plate!$I$2:$J$97,2,FALSE) ), VLOOKUP(C8,Source_Plate!$E$2:$F$97,2,FALSE) ) ) | B8: =IF(C8="","",'Plan+'!K8) | C8: =IF('Plan+'!I8="","",'Plan+'!I8) | D8: =IF(C8="","",'Plate organization+'!$B$46) | E8: ='Plan+'!L8 -> Destination_Plate_1
A9: =IF(C9="", "", IF(ISERROR(VLOOKUP(C9,Source_Plate!$E$2:$F$97,2,FALSE)), IF(ISERROR(VLOOKUP(C9,Source_Plate!$I$2:$J$97,2,FALSE)), "", VLOOKUP(C9,Source_Plate!$I$2:$J$97,2,FALSE) ), VLOOKUP(C9,Source_Plate!$E$2:$F$97,2,FALSE) ) ) | B9: =IF(C9="","",'Plan+'!K9) | C9: =IF('Plan+'!I9="","",'Plan+'!I9) | D9: =IF(C9="","",'Plate organization+'!$B$46) | E9: ='Plan+'!L9 -> Destination_Plate_1
A10: =IF(C10="", "", IF(ISERROR(VLOOKUP(C10,Source_Plate!$E$2:$F$97,2,FALSE)), IF(ISERROR(VLOOKUP(C10,Source_Plate!$I$2:$J$97,2,FALSE)), "", VLOOKUP(C10,Source_Plate!$I$2:$J$97,2,FALSE) ), VLOOKUP(C10,Source_Plate!$E$2:$F$97,2,FALSE) ) ) | B10: =IF(C10="","",'Plan+'!K10) | C10: =IF('Plan+'!I10="","",'Plan+'!I10) | D10: =IF(C10="","",'Plate organization+'!$B$46) | E10: ='Plan+'!L10 -> Destination_Plate_1
A11: =IF(C11="", "", IF(ISERROR(VLOOKUP(C11,Source_Plate!$E$2:$F$97,2,FALSE)), IF(ISERROR(VLOOKUP(C11,Source_Plate!$I$2:$J$97,2,FALSE)), "", VLOOKUP(C11,Source_Plate!$I$2:$J$97,2,FALSE) ), VLOOKUP(C11,Source_Plate!$E$2:$F$97,2,FALSE) ) ) | B11: =IF(C11="","",'Plan+'!K11) | C11: =IF('Plan+'!I11="","",'Plan+'!I11) | D11: =IF(C11="","",'Plate organization+'!$B$46) | E11: ='Plan+'!L11 -> Destination_Plate_1
A12: =IF(C12="", "", IF(ISERROR(VLOOKUP(C12,Source_Plate!$E$2:$F$97,2,FALSE)), IF(ISERROR(VLOOKUP(C12,Source_Plate!$I$2:$J$97,2,FALSE)), "", VLOOKUP(C12,Source_Plate!$I$2:$J$97,2,FALSE) ), VLOOKUP(C12,Source_Plate!$E$2:$F$97,2,FALSE) ) ) | B12: =IF(C12="","",'Plan+'!K12) | C12: =IF('Plan+'!I12="","",'Plan+'!I12) | D12: =IF(C12="","",'Plate organization+'!$B$46) | E12: ='Plan+'!L12 -> Destination_Plate_1
A13: =IF(C13="", "", IF(ISERROR(VLOOKUP(C13,Source_Plate!$E$2:$F$97,2,FALSE)), IF(ISERROR(VLOOKUP(C13,Source_Plate!$I$2:$J$97,2,FALSE)), "", VLOOKUP(C13,Source_Plate!$I$2:$J$97,2,FALSE) ), VLOOKUP(C13,Source_Plate!$E$2:$F$97,2,FALSE) ) ) | B13: =IF(C13="","",'Plan+'!K13) | C13: =IF('Plan+'!I13="","",'Plan+'!I13) | D13: =IF(C13="","",'Plate organization+'!$B$46) | E13: ='Plan+'!L13 -> Destination_Plate_1
... A97: =IF(C97="", "", IF(ISERROR(VLOOKUP(C97,Source_Plate!$E$2:$F$97,2,FALSE)), IF(ISERROR(VLOOKUP(C97,Source_Plate!$I$2:$J$97,2,FALSE)), "", VLOOKUP(C97,Source_Plate!$I$2:$J$97,2,FALSE) ), VLOOKUP(C97,Source_Plate!$E$2:$F$97,2,FALSE) ) ) | B97: =IF(C97="","",'Plan+'!K97) | C97: =IF('Plan+'!I97="","",'Plan+'!I97) | D97: =IF(C97="","",'Plate organization+'!$B$46) | E97: ='Plan+'!L97 -> Destination_Plate_1

Sheet Worklist_MM
A1: Well Nr. source plate | B1: Well Nr. destination plate | C1: Part | D1: Volumen | E1: Destination_plate
A2: =IF(C2="", "", IF(ISERROR(VLOOKUP(C2,Source_Plate!$E$2:$F$97,2,FALSE)), IF(ISERROR(VLOOKUP(C2,Source_Plate!$I$2:$J$97,2,FALSE)), "", VLOOKUP(C2,Source_Plate!$I$2:$J$97,2,FALSE) ), VLOOKUP(C2,Source_Plate!$E$2:$F$97,2,FALSE) ) ) -> A01 | B2: =IF(C2="","",'Plan+'!K2) -> A01 | C2: =IF('Plan+'!B2="","",'Plan+'!B2) -> Mastermix1 | D2: =IF(C2="","",'Plate organization+'!$B$40) -> 4 | E2: ='Plan+'!L2 -> Destination_Plate_1
A3: =IF(C3="", "", IF(ISERROR(VLOOKUP(C3,Source_Plate!$E$2:$F$97,2,FALSE)), IF(ISERROR(VLOOKUP(C3,Source_Plate!$I$2:$J$97,2,FALSE)), "", VLOOKUP(C3,Source_Plate!$I$2:$J$97,2,FALSE) ), VLOOKUP(C3,Source_Plate!$E$2:$F$97,2,FALSE) ) ) -> A01 | B3: =IF(C3="","",'Plan+'!K3) -> B01 | C3: =IF('Plan+'!B3="","",'Plan+'!B3) -> Mastermix1 | D3: =IF(C3="","",'Plate organization+'!$B$40) -> 4 | E3: ='Plan+'!L3 -> Destination_Plate_1
