Workbook

Sheet Infos+

Sheet Plate organization+
A1: mtp_primer_stocks
A2: Plate I | B2: 1 | C2: 2 | D2: 3 | E2: 4 | F2: 5 | G2: 6 | H2: 7 | I2: 8 | J2: 9 | K2: 10 | L2: 11 | M2: 12
A3: A | B3: UNS1_fwd
A4: B | B4: UNS4_rev
A5: C | B5: UNS4_fwd
A6: D | B6: UNS10_rev
A7: E
A8: F
A9: G
A10: H
A13: mtp_source
A14: Plate I | B14: 1 | C14: 2 | D14: 3 | E14: 4 | F14: 5 | G14: 6 | H14: 7 | I14: 8 | J14: 9 | K14: 10 | L14: 11 | M14: 12
A15: A | B15: UNS1_fwd und UNS4_rev | D15: Mastermix1
A16: B | B16: UNS4_fwd und UNS10_rev
A17: C
A18: D
A19: E
A20: F
A21: G
A22: H
A25: mtp_template_DNA
A26: Plate I | B26: 1 | C26: 2 | D26: 3 | E26: 4 | F26: 5 | G26: 6 | H26: 7 | I26: 8 | J26: 9 | K26: 10 | L26: 11 | M26: 12
A27: A | B27: Template 1
A28: B | B28: Template 2
A29: C
A30: D
A31: E
A32: F
A33: G
A34: H
B36: Only change blue cells
A37: Meta data | B37: Value | E37: PCR Mastermix calculator
A38: Volume per Primer in Primer Mix [µL] | B38: 10 | E38: Number Reactions | F38: 1
A39: Volume per Primer Mix total [µL] (Max = 400) | B39: =B38*2 -> 20 | C39: Auto calculation | E39: 2x Q5 Mix | F39: =F43/2 -> 25
A40: Volume Mastermix per reaction [µL] | B40: =F42/F38 -> 40 | C40: Auto calculation | E40: DMSO | F40: =F43/20 -> 2.5
A41: Volume Primer Pair added per reaction [µL] | B41: 5 | C41: =IF(B41,"","<-- Value missing") | E41: H2O | F41: =B45-F39-F40-B41-B42 -> 12.5
A42: Volume Template DNA addded per reaction [µL] | B42: 5 | C42: =IF(B42,"","<-- Value missing") | E42: Volume Mastermix per PCR reaction [µL] | F42: =SUM(F39:F41) -> 40
A43: Volume Water Dilution Template [µL] | C43: <-- Leave empty when no template dilution is needed | E43: Total volume per PCR reaction [µL] | F43: =B45 -> 50 | G43: Value taken from B45
A44: Volume Template Total [µL]
A45: Total volume per PCR reaction [µL] | B45: 50 | C45: =IF(B45,"","<-- Value missing")

Sheet PM_info+
A1: Nr. | B1: Well | C1: Primermix | D1: Primer 1 | E1: Primer 2
A2: 1 | B2: A01 | C2: UNS1_fwd und UNS4_rev | D2: UNS1_fwd | E2: UNS4_rev
A3: 2 | B3: B01 | C3: UNS4_fwd und UNS10_rev | D3: UNS4_fwd | E3: UNS10_rev
A4: 3 | B4: C01
A5: 4 | B5: D01
A6: 5 | B6: E01
A7: 6 | B7: F01
A8: 7 | B8: G01
A9: 8 | B9: H01
A10: 9 | B10: A02
A11: 10 | B11: B02
A12: 11 | B12: C02
A13: 12 | B13: D02
A14: 13 | B14: E02
A15: 14 | B15: F02
... A97: 96 | B97: H12

Sheet Plan+
A1: Nr. | B1: Primer pairs | C1: Template | D1: Mastermix | E1: Water | F1: Well | G1: Plate | H1: Description
A2: 1 | B2: UNS1_fwd und UNS4_rev | C2: Template 1 | D2: Mastermix1 | E2: water | F2: A01 | G2: Destination_Plate_1
A3: 2 | B3: UNS4_fwd und UNS10_rev | C3: Template 2 | D3: Mastermix1 | E3: water | F3: B01 | G3: Destination_Plate_1
A4: 3 | F4: C01 | G4: Destination_Plate_1
A5: 4 | F5: D01 | G5: Destination_Plate_1
A6: 5 | F6: E01 | G6: Destination_Plate_1
A7: 6 | F7: F01 | G7: Destination_Plate_1
A8: 7 | F8: G01 | G8: Destination_Plate_1
A9: 8 | F9: H01 | G9: Destination_Plate_1
A10: 9 | F10: A02 | G10: Destination_Plate_1
A11: 10 | F11: B02 | G11: Destination_Plate_1
A12: 11 | F12: C02 | G12: Destination_Plate_1
A13: 12 | F13: D02 | G13: Destination_Plate_1
A14: 13 | F14: E02 | G14: Destination_Plate_1
A15: 14 | F15: F02 | G15: Destination_Plate_1
... A97: 96 | F97: H12 | G97: Destination_Plate_1

Sheet Source_Plate
A1: Content | B1: Well | C1: MTP | E1: Content | F1: Well | G1: MTP | I1: Content | J1: Well | K1: MTP | M1: Trough | N1: Well | O1: MTP Template
A2: =IF('Plate organization+'!B15="","",'Plate organization+'!B15) -> UNS1_fwd und UNS4_rev | B2: A01 | C2: =IF(A2=0,"",A2) -> UNS1_fwd und UNS4_rev | E2: =IF('Plate organization+'!B3="","",'Plate organization+'!B3) -> UNS1_fwd | F2: A01 | G2: =IF(E2=0,"",E2) -> UNS1_fwd | I2: =IF('Plate organization+'!B27="","",'Plate organization+'!B27) -> Template 1 | J2: A01 | K2: =IF(I2=0,"",I2) -> Template 1 | M2: water | N2: A01 | O2: =IF(M2=0,"",M2) -> water
A3: =IF('Plate organization+'!B16="","",'Plate organization+'!B16) -> UNS4_fwd und UNS10_rev | B3: B01 | C3: =IF(A3=0,"",A3) -> UNS4_fwd und UNS10_rev | E3: =IF('Plate organization+'!B4="","",'Plate organization+'!B4) -> UNS4_rev | F3: B01 | G3: =IF(E3=0,"",E3) -> UNS4_rev | I3: =IF('Plate organization+'!B28="","",'Plate organization+'!B28) -> Template 2 | J3: B01 | K3: =IF(I3=0,"",I3) -> Template 2 | N3: B01 | O3: =IF(M3=0,"",M3)
A4: =IF('Plate organization+'!B17="","",'Plate organization+'!B17) | B4: C01 | C4: =IF(A4=0,"",A4) | E4: =IF('Plate organization+'!B5="","",'Plate organization+'!B5) -> UNS4_fwd | F4: C01 | G4: =IF(E4=0,"",E4) -> UNS4_fwd | I4: =IF('Plate organization+'!B29="","",'Plate organization+'!B29) | J4: C01 | K4: =IF(I4=0,"",I4) | N4: C01 | O4: =IF(M4=0,"",M4)
A5: =IF('Plate organization+'!B18="","",'Plate organization+'!B18) | B5: D01 | C5: =IF(A5=0,"",A5) | E5: =IF('Plate organization+'!B6="","",'Plate organization+'!B6) -> UNS10_rev | F5: D01 | G5: =IF(E5=0,"",E5) -> UNS10_rev | I5: =IF('Plate organization+'!B30="","",'Plate organization+'!B30) | J5: D01 | K5: =IF(I5=0,"",I5) | N5: D01 | O5: =IF(M5=0,"",M5)
A6: =IF('Plate organization+'!B19="","",'Plate organization+'!B19) | B6: E01 | C6: =IF(A6=0,"",A6) | E6: =IF('Plate organization+'!B7="","",'Plate organization+'!B7) | F6: E01 | G6: =IF(E6=0,"",E6) | I6: =IF('Plate organization+'!B31="","",'Plate organization+'!B31) | J6: E01 | K6: =IF(I6=0,"",I6) | N6: E01 | O6: =IF(M6=0,"",M6)
A7: =IF('Plate organization+'!B20="","",'Plate organization+'!B20) | B7: F01 | C7: =IF(A7=0,"",A7) | E7: =IF('Plate organization+'!B8="","",'Plate organization+'!B8) | F7: F01 | G7: =IF(E7=0,"",E7) | I7: =IF('Plate organization+'!B32="","",'Plate organization+'!B32) | J7: F01 | K7: =IF(I7=0,"",I7) | N7: F01 | O7: =IF(M7=0,"",M7)
A8: =IF('Plate organization+'!B21="","",'Plate organization+'!B21) | B8: G01 | C8: =IF(A8=0,"",A8) | E8: =IF('Plate organization+'!B9="","",'Plate organization+'!B9) | F8: G01 | G8: =IF(E8=0,"",E8) | I8: =IF('Plate organization+'!B33="","",'Plate organization+'!B33) | J8: G01 | K8: =IF(I8=0,"",I8) | N8: G01 | O8: =IF(M8=0,"",M8)
A9: =IF('Plate organization+'!B22="","",'Plate organization+'!B22) | B9: H01 | C9: =IF(A9=0,"",A9) | E9: =IF('Plate organization+'!B10="","",'Plate organization+'!B10) | F9: H01 | G9: =IF(E9=0,"",E9) | I9: =IF('Plate organization+'!B34="","",'Plate organization+'!B34) | J9: H01 | K9: =IF(I9=0,"",I9) | N9: H01 | O9: =IF(M9=0,"",M9)
A10: =IF('Plate organization+'!C15="","",'Plate organization+'!C15) | B10: A02 | C10: =IF(A10=0,"",A10) | E10: =IF('Plate organization+'!C3="","",'Plate organization+'!C3) | F10: A02 | G10: =IF(E10=0,"",E10) | I10: =IF('Plate organization+'!C27="","",'Plate organization+'!C27) | J10: A02 | K10: =IF(I10=0,"",I10)
A11: =IF('Plate organization+'!C16="","",'Plate organization+'!C16) | B11: B02 | C11: =IF(A11=0,"",A11) | E11: =IF('Plate organization+'!C4="","",'Plate organization+'!C4) | F11: B02 | G11: =IF(E11=0,"",E11) | I11: =IF('Plate organization+'!C28="","",'Plate organization+'!C28) | J11: B02 | K11: =IF(I11=0,"",I11)
A12: =IF('Plate organization+'!C17="","",'Plate organization+'!C17) | B12: C02 | C12: =IF(A12=0,"",A12) | E12: =IF('Plate organization+'!C5="","",'Plate organization+'!C5) | F12: C02 | G12: =IF(E12=0,"",E12) | I12: =IF('Plate organization+'!C29="","",'Plate organization+'!C29) | J12: C02 | K12: =IF(I12=0,"",I12)
A13: =IF('Plate organization+'!C18="","",'Plate organization+'!C18) | B13: D02 | C13: =IF(A13=0,"",A13) | E13: =IF('Plate organization+'!C6="","",'Plate organization+'!C6) | F13: D02 | G13: =IF(E13=0,"",E13) | I13: =IF('Plate organization+'!C30="","",'Plate organization+'!C30) | J13: D02 | K13: =IF(I13=0,"",I13)
A14: =IF('Plate organization+'!C19="","",'Plate organization+'!C19) | B14: E02 | C14: =IF(A14=0,"",A14) | E14: =IF('Plate organization+'!C7="","",'Plate organization+'!C7) | F14: E02 | G14: =IF(E14=0,"",E14) | I14: =IF('Plate organization+'!C31="","",'Plate organization+'!C31) | J14: E02 | K14: =IF(I14=0,"",I14)
A15: =IF('Plate organization+'!C20="","",'Plate organization+'!C20) | B15: F02 | C15: =IF(A15=0,"",A15) | E15: =IF('Plate organization+'!C8="","",'Plate organization+'!C8) | F15: F02 | G15: =IF(E15=0,"",E15) | I15: =IF('Plate organization+'!C32="","",'Plate organization+'!C32) | J15: F02 | K15: =IF(I15=0,"",I15)
A16: =IF('Plate organization+'!C21="","",'Plate organization+'!C21) | B16: G02 | C16: =IF(A16=0,"",A16) | E16: =IF('Plate organization+'!C9="","",'Plate organization+'!C9) | F16: G02 | G16: =IF(E16=0,"",E16) | I16: =IF('Plate organization+'!C33="","",'Plate organization+'!C33) | J16: G02 | K16: =IF(I16=0,"",I16)
A17: =IF('Plate organization+'!C22="","",'Plate organization+'!C22) | B17: H02 | C17: =IF(A17=0,"",A17) | E17: =IF('Plate organization+'!C10="","",'Plate organization+'!C10) | F17: H02 | G17: =IF(E17=0,"",E17) | I17: =IF('Plate organization+'!C34="","",'Plate organization+'!C34) | J17: H02 | K17: =IF(I17=0,"",I17)
A18: =IF('Plate organization+'!D15="","",'Plate organization+'!D15) -> Mastermix1 | B18: A03 | C18: =IF(A18=0,"",A18) -> Mastermix1 | E18: =IF('Plate organization+'!D3="","",'Plate organization+'!D3) | F18: A03 | G18: =IF(E18=0,"",E18) | I18: =IF('Plate organization+'!D27="","",'Plate organization+'!D27) | J18: A03 | K18: =IF(I18=0,"",I18)
A19: =IF('Plate organization+'!D16="","",'Plate organization+'!D16) | B19: B03 | C19: =IF(A19=0,"",A19) | E19: =IF('Plate organization+'!D4="","",'Plate organization+'!D4) | F19: B03 | G19: =IF(E19=0,"",E19) | I19: =IF('Plate organization+'!D28="","",'Plate organization+'!D28) | J19: B03 | K19: =IF(I19=0,"",I19)
A20: =IF('Plate organization+'!D17="","",'Plate organization+'!D17) | B20: C03 | C20: =IF(A20=0,"",A20) | E20: =IF('Plate organization+'!D5="","",'Plate organization+'!D5) | F20: C03 | G20: =IF(E20=0,"",E20) | I20: =IF('Plate organization+'!D29="","",'Plate organization+'!D29) | J20: C03 | K20: =IF(I20=0,"",I20)
A21: =IF('Plate organization+'!D18="","",'Plate organization+'!D18) | B21: D03 | C21: =IF(A21=0,"",A21) | E21: =IF('Plate organization+'!D6="","",'Plate organization+'!D6) | F21: D03 | G21: =IF(E21=0,"",E21) | I21: =IF('Plate organization+'!D30="","",'Plate organization+'!D30) | J21: D03 | K21: =IF(I21=0,"",I21)
A22: =IF('Plate organization+'!D19="","",'Plate organization+'!D19) | B22: E03 | C22: =IF(A22=0,"",A22) | E22: =IF('Plate organization+'!D7="","",'Plate organization+'!D7) | F22: E03 | G22: =IF(E22=0,"",E22) | I22: =IF('Plate organization+'!D31="","",'Plate organization+'!D31) | J22: E03 | K22: =IF(I22=0,"",I22)
A23: =IF('Plate organization+'!D20="","",'Plate organization+'!D20) | B23: F03 | C23: =IF(A23=0,"",A23) | E23: =IF('Plate organization+'!D8="","",'Plate organization+'!D8) | F23: F03 | G23: =IF(E23=0,"",E23) | I23: =IF('Plate organization+'!D32="","",'Plate organization+'!D32) | J23: F03 | K23: =IF(I23=0,"",I23)
A24: =IF('Plate organization+'!D21="","",'Plate organization+'!D21) | B24: G03 | C24: =IF(A24=0,"",A24) | E24: =IF('Plate organization+'!D9="","",'Plate organization+'!D9) | F24: G03 | G24: =IF(E24=0,"",E24) | I24: =IF('Plate organization+'!D33="","",'Plate organization+'!D33) | J24: G03 | K24: =IF(I24=0,"",I24)
A25: =IF('Plate organization+'!D22="","",'Plate organization+'!D22) | B25: H03 | C25: =IF(A25=0,"",A25) | E25: =IF('Plate organization+'!D10="","",'Plate organization+'!D10) | F25: H03 | G25: =IF(E25=0,"",E25) | I25: =IF('Plate organization+'!D34="","",'Plate organization+'!D34) | J25: H03 | K25: =IF(I25=0,"",I25)
A26: =IF('Plate organization+'!E15="","",'Plate organization+'!E15) | B26: A04 | C26: =IF(A26=0,"",A26) | E26: =IF('Plate organization+'!E3="","",'Plate organization+'!E3) | F26: A04 | G26: =IF(E26=0,"",E26) | I26: =IF('Plate organization+'!E27="","",'Plate organization+'!E27) | J26: A04 | K26: =IF(I26=0,"",I26)
A27: =IF('Plate organization+'!E16="","",'Plate organization+'!E16) | B27: B04 | C27: =IF(A27=0,"",A27) | E27: =IF('Plate organization+'!E4="","",'Plate organization+'!E4) | F27: B04 | G27: =IF(E27=0,"",E27) | I27: =IF('Plate organization+'!E28="","",'Plate organization+'!E28) | J27: B04 | K27: =IF(I27=0,"",I27)
A28: =IF('Plate organization+'!E17="","",'Plate organization+'!E17) | B28: C04 | C28: =IF(A28=0,"",A28) | E28: =IF('Plate organization+'!E5="","",'Plate organization+'!E5) | F28: C04 | G28: =IF(E28=0,"",E28) | I28: =IF('Plate organization+'!E29="","",'Plate organization+'!E29) | J28: C04 | K28: =IF(I28=0,"",I28)
A29: =IF('Plate organization+'!E18="","",'Plate organization+'!E18) | B29: D04 | C29: =IF(A29=0,"",A29) | E29: =IF('Plate organization+'!E6="","",'Plate organization+'!E6) | F29: D04 | G29: =IF(E29=0,"",E29) | I29: =IF('Plate organization+'!E30="","",'Plate organization+'!E30) | J29: D04 | K29: =IF(I29=0,"",I29)
A30: =IF('Plate organization+'!E19="","",'Plate organization+'!E19) | B30: E04 | C30: =IF(A30=0,"",A30) | E30: =IF('Plate organization+'!E7="","",'Plate organization+'!E7) | F30: E04 | G30: =IF(E30=0,"",E30) | I30: =IF('Plate organization+'!E31="","",'Plate organization+'!E31) | J30: E04 | K30: =IF(I30=0,"",I30)
A31: =IF('Plate organization+'!E20="","",'Plate organization+'!E20) | B31: F04 | C31: =IF(A31=0,"",A31) | E31: =IF('Plate organization+'!E8="","",'Plate organization+'!E8) | F31: F04 | G31: =IF(E31=0,"",E31) | I31: =IF('Plate organization+'!E32="","",'Plate organization+'!E32) | J31: F04 | K31: =IF(I31=0,"",I31)
A32: =IF('Plate organization+'!E21="","",'Plate organization+'!E21) | B32: G04 | C32: =IF(A32=0,"",A32) | E32: =IF('Plate organization+'!E9="","",'Plate organization+'!E9) | F32: G04 | G32: =IF(E32=0,"",E32) | I32: =IF('Plate organization+'!E33="","",'Plate organization+'!E33) | J32: G04 | K32: =IF(I32=0,"",I32)
A33: =IF('Plate organization+'!E22="","",'Plate organization+'!E22) | B33: H04 | C33: =IF(A33=0,"",A33) | E33: =IF('Plate organization+'!E10="","",'Plate organization+'!E10) | F33: H04 | G33: =IF(E33=0,"",E33) | I33: =IF('Plate organization+'!E34="","",'Plate organization+'!E34) | J33: H04 | K33: =IF(I33=0,"",I33)
A34: =IF('Plate organization+'!F15="","",'Plate organization+'!F15) | B34: A05 | C34: =IF(A34=0,"",A34) | E34: =IF('Plate organization+'!F3="","",'Plate organization+'!F3) | F34: A05 | G34: =IF(E34=0,"",E34) | I34: =IF('Plate organization+'!F27="","",'Plate organization+'!F27) | J34: A05 | K34: =IF(I34=0,"",I34)
A35: =IF('Plate organization+'!F16="","",'Plate organization+'!F16) | B35: B05 | C35: =IF(A35=0,"",A35) | E35: =IF('Plate organization+'!F4="","",'Plate organization+'!F4) | F35: B05 | G35: =IF(E35=0,"",E35) | I35: =IF('Plate organization+'!F28="","",'Plate organization+'!F28) | J35: B05 | K35: =IF(I35=0,"",I35)
A36: =IF('Plate organization+'!F17="","",'Plate organization+'!F17) | B36: C05 | C36: =IF(A36=0,"",A36) | E36: =IF('Plate organization+'!F5="","",'Plate organization+'!F5) | F36: C05 | G36: =IF(E36=0,"",E36) | I36: =IF('Plate organization+'!F29="","",'Plate organization+'!F29) | J36: C05 | K36: =IF(I36=0,"",I36)
A37: =IF('Plate organization+'!F18="","",'Plate organization+'!F18) | B37: D05 | C37: =IF(A37=0,"",A37) | E37: =IF('Plate organization+'!F6="","",'Plate organization+'!F6) | F37: D05 | G37: =IF(E37=0,"",E37) | I37: =IF('Plate organization+'!F30="","",'Plate organization+'!F30) | J37: D05 | K37: =IF(I37=0,"",I37)
A38: =IF('Plate organization+'!F19="","",'Plate organization+'!F19) | B38: E05 | C38: =IF(A38=0,"",A38) | E38: =IF('Plate organization+'!F7="","",'Plate organization+'!F7) | F38: E05 | G38: =IF(E38=0,"",E38) | I38: =IF('Plate organization+'!F31="","",'Plate organization+'!F31) | J38: E05 | K38: =IF(I38=0,"",I38)
A39: =IF('Plate organization+'!F20="","",'Plate organization+'!F20) | B39: F05 | C39: =IF(A39=0,"",A39) | E39: =IF('Plate organization+'!F8="","",'Plate organization+'!F8) | F39: F05 | G39: =IF(E39=0,"",E39) | I39: =IF('Plate organization+'!F32="","",'Plate organization+'!F32) | J39: F05 | K39: =IF(I39=0,"",I39)
A40: =IF('Plate organization+'!F21="","",'Plate organization+'!F21) | B40: G05 | C40: =IF(A40=0,"",A40) | E40: =IF('Plate organization+'!F9="","",'Plate organization+'!F9) | F40: G05 | G40: =IF(E40=0,"",E40) | I40: =IF('Plate organization+'!F33="","",'Plate organization+'!F33) | J40: G05 | K40: =IF(I40=0,"",I40)
...

Sheet Worklist_Water
A1: Well Nr. source plate | B1: Well Nr. destination plate | C1: Part | D1: Volumen | E1: Destination_plate
A2: =IF(C2="","",VLOOKUP(C2,Source_Plate!$M$2:$N$9,2,FALSE)) | B2: =IF(C2="","",'Plan+'!F2) | C2: =IF(OR('Plan+'!E2="",'Plate organization+'!$B$43="",'Plate organization+'!$B$43=0),"",'Plan+'!E2) | D2: =IF(C2="","",'Plate organization+'!$B$43) | E2: Template
A3: =IF(C3="","",VLOOKUP(C3,Source_Plate!$M$2:$N$9,2,FALSE)) | B3: =IF(C3="","",'Plan+'!F3) | C3: =IF(OR('Plan+'!E3="",'Plate organization+'!$B$43="",'Plate organization+'!$B$43=0),"",'Plan+'!E3) | D3: =IF(C3="","",'Plate organization+'!$B$43) | E3: Template
A4: =IF(C4="","",VLOOKUP(C4,Source_Plate!$M$2:$N$9,2,FALSE)) | B4: =IF(C4="","",'Plan+'!F4) | C4: =IF(OR('Plan+'!E4="",'Plate organization+'!$B$43="",'Plate organization+'!$B$43=0),"",'Plan+'!E4) | D4: =IF(C4="","",'Plate organization+'!$B$43) | E4: Template
A5: =IF(C5="","",VLOOKUP(C5,Source_Plate!$M$2:$N$9,2,FALSE)) | B5: =IF(C5="","",'Plan+'!F5) | C5: =IF(OR('Plan+'!E5="",'Plate organization+'!$B$43="",'Plate organization+'!$B$43=0),"",'Plan+'!E5) | D5: =IF(C5="","",'Plate organization+'!$B$43) | E5: Template
A6: =IF(C6="","",VLOOKUP(C6,Source_Plate!$M$2:$N$9,2,FALSE)) | B6: =IF(C6="","",'Plan+'!F6) | C6: =IF(OR('Plan+'!E6="",'Plate organization+'!$B$43="",'Plate organization+'!$B$43=0),"",'Plan+'!E6) | D6: =IF(C6="","",'Plate organization+'!$B$43) | E6: Template
A7: =IF(C7="","",VLOOKUP(C7,Source_Plate!$M$2:$N$9,2,FALSE)) | B7: =IF(C7="","",'Plan+'!F7) | C7: =IF(OR('Plan+'!E7="",'Plate organization+'!$B$43="",'Plate organization+'!$B$43=0),"",'Plan+'!E7) | D7: =IF(C7="","",'Plate organization+'!$B$43) | E7: Template
A8: =IF(C8="","",VLOOKUP(C8,Source_Plate!$M$2:$N$9,2,FALSE)) | B8: =IF(C8="","",'Plan+'!F8) | C8: =IF(OR('Plan+'!E8="",'Plate organization+'!$B$43="",'Plate organization+'!$B$43=0),"",'Plan+'!E8) | D8: =IF(C8="","",'Plate organization+'!$B$43) | E8: Template
A9: =IF(C9="","",VLOOKUP(C9,Source_Plate!$M$2:$N$9,2,FALSE)) | B9: =IF(C9="","",'Plan+'!F9) | C9: =IF(OR('Plan+'!E9="",'Plate organization+'!$B$43="",'Plate organization+'!$B$43=0),"",'Plan+'!E9) | D9: =IF(C9="","",'Plate organization+'!$B$43) | E9: Template
A10: =IF(C10="","",VLOOKUP(C10,Source_Plate!$M$2:$N$9,2,FALSE)) | B10: =IF(C10="","",'Plan+'!F10) | C10: =IF(OR('Plan+'!E10="",'Plate organization+'!$B$43="",'Plate organization+'!$B$43=0),"",'Plan+'!E10) | D10: =IF(C10="","",'Plate organization+'!$B$43) | E10: Template
A11: =IF(C11="","",VLOOKUP(C11,Source_Plate!$M$2:$N$9,2,FALSE)) | B11: =IF(C11="","",'Plan+'!F11) | C11: =IF(OR('Plan+'!E11="",'Plate organization+'!$B$43="",'Plate organization+'!$B$43=0),"",'Plan+'!E11) | D11: =IF(C11="","",'Plate organization+'!$B$43) | E11: Template
A12: =IF(C12="","",VLOOKUP(C12,Source_Plate!$M$2:$N$9,2,FALSE)) | B12: =IF(C12="","",'Plan+'!F12) | C12: =IF(OR('Plan+'!E12="",'Plate organization+'!$B$43="",'Plate organization+'!$B$43=0),"",'Plan+'!E12) | D12: =IF(C12="","",'Plate organization+'!$B$43) | E12: Template
A13: =IF(C13="","",VLOOKUP(C13,Source_Plate!$M$2:$N$9,2,FALSE)) | B13: =IF(C13="","",'Plan+'!F13) | C13: =IF(OR('Plan+'!E13="",'Plate organization+'!$B$43="",'Plate organization+'!$B$43=0),"",'Plan+'!E13) | D13: =IF(C13="","",'Plate organization+'!$B$43) | E13: Template
... A97: =IF(C97="","",VLOOKUP(C97,Source_Plate!$M$2:$N$9,2,FALSE)) | B97: =IF(C97="","",'Plan+'!F97) | C97: =IF(OR('Plan+'!E97="",'Plate organization+'!$B$43="",'Plate organization+'!$B$43=0),"",'Plan+'!E97) | D97: =IF(C97="","",'Plate organization+'!$B$43) | E97: Template
B98: =COUNTA(B2:B97) -> 96

Sheet Worklist_Template
A1: Well Nr. source plate | B1: Well Nr. destination plate | C1: Part | D1: Volumen | E1: Destination_plate | F1: Source_plate
A2: =IF(C2="","",VLOOKUP(C2,Source_Plate!$I$2:$J$97,2,FALSE)) -> A01 | B2: =IF(C2="","",'Plan+'!F2) -> A01 | C2: =IF('Plan+'!C2="","",'Plan+'!C2) -> Template 1 | D2: =IF(C2="","",'Plate organization+'!$B$42) -> 5 | E2: ='Plan+'!G2 -> Destination_Plate_1 | F2: ='Plate organization+'!$A$13 -> mtp_source
A3: =IF(C3="","",VLOOKUP(C3,Source_Plate!$I$2:$J$97,2,FALSE)) -> B01 | B3: =IF(C3="","",'Plan+'!F3) -> B01 | C3: =IF('Plan+'!C3="","",'Plan+'!C3) -> Template 2 | D3: =IF(C3="","",'Plate organization+'!$B$42) -> 5 | E3: ='Plan+'!G3 -> Destination_Plate_1 | F3: ='Plate organization+'!$A$13 -> mtp_source
A4: =IF(C4="","",VLOOKUP(C4,Source_Plate!$I$2:$J$97,2,FALSE)) | B4: =IF(C4="","",'Plan+'!F4) | C4: =IF('Plan+'!C4="","",'Plan+'!C4) | D4: =IF(C4="","",'Plate organization+'!$B$42) | E4: ='Plan+'!G4 -> Destination_Plate_1 | F4: ='Plate organization+'!$A$13 -> mtp_source
A5: =IF(C5="","",VLOOKUP(C5,Source_Plate!$I$2:$J$97,2,FALSE)) | B5: =IF(C5="","",'Plan+'!F5) | C5: =IF('Plan+'!C5="","",'Plan+'!C5) | D5: =IF(C5="","",'Plate organization+'!$B$42) | E5: ='Plan+'!G5 -> Destination_Plate_1 | F5: ='Plate organization+'!$A$13 -> mtp_source
A6: =IF(C6="","",VLOOKUP(C6,Source_Plate!$I$2:$J$97,2,FALSE)) | B6: =IF(C6="","",'Plan+'!F6) | C6: =IF('Plan+'!C6="","",'Plan+'!C6) | D6: =IF(C6="","",'Plate organization+'!$B$42) | E6: ='Plan+'!G6 -> Destination_Plate_1 | F6: ='Plate organization+'!$A$13 -> mtp_source
A7: =IF(C7="","",VLOOKUP(C7,Source_Plate!$I$2:$J$97,2,FALSE)) | B7: =IF(C7="","",'Plan+'!F7) | C7: =IF('Plan+'!C7="","",'Plan+'!C7) | D7: =IF(C7="","",'Plate organization+'!$B$42) | E7: ='Plan+'!G7 -> Destination_Plate_1 | F7: ='Plate organization+'!$A$13 -> mtp_source
A8: =IF(C8="","",VLOOKUP(C8,Source_Plate!$I$2:$J$97,2,FALSE)) | B8: =IF(C8="","",'Plan+'!F8) | C8: =IF('Plan+'!C8="","",'Plan+'!C8) | D8: =IF(C8="","",'Plate organization+'!$B$42) | E8: ='Plan+'!G8 -> Destination_Plate_1 | F8: ='Plate organization+'!$A$13 -> mtp_source
A9: =IF(C9="","",VLOOKUP(C9,Source_Plate!$I$2:$J$97,2,FALSE)) | B9: =IF(C9="","",'Plan+'!F9) | C9: =IF('Plan+'!C9="","",'Plan+'!C9) | D9: =IF(C9="","",'Plate organization+'!$B$42) | E9: ='Plan+'!G9 -> Destination_Plate_1 | F9: ='Plate organization+'!$A$13 -> mtp_source
A10: =IF(C10="","",VLOOKUP(C10,Source_Plate!$I$2:$J$97,2,FALSE)) | B10: =IF(C10="","",'Plan+'!F10) | C10: =IF('Plan+'!C10="","",'Plan+'!C10) | D10: =IF(C10="","",'Plate organization+'!$B$42) | E10: ='Plan+'!G10 -> Destination_Plate_1 | F10: ='Plate organization+'!$A$13 -> mtp_source
A11: =IF(C11="","",VLOOKUP(C11,Source_Plate!$I$2:$J$97,2,FALSE)) | B11: =IF(C11="","",'Plan+'!F11) | C11: =IF('Plan+'!C11="","",'Plan+'!C11) | D11: =IF(C11="","",'Plate organization+'!$B$42) | E11: ='Plan+'!G11 -> Destination_Plate_1 | F11: ='Plate organization+'!$A$13 -> mtp_source
A12: =IF(C12="","",VLOOKUP(C12,Source_Plate!$I$2:$J$97,2,FALSE)) | B12: =IF(C12="","",'Plan+'!F12) | C12: =IF('Plan+'!C12="","",'Plan+'!C12) | D12: =IF(C12="","",'Plate organization+'!$B$42) | E12: ='Plan+'!G12 -> Destination_Plate_1 | F12: ='Plate organization+'!$A$13 -> mtp_source
A13: =IF(C13="","",VLOOKUP(C13,Source_Plate!$I$2:$J$97,2,FALSE)) | B13: =IF(C13="","",'Plan+'!F13) | C13: =IF('Plan+'!C13="","",'Plan+'!C13) | D13: =IF(C13="","",'Plate organization+'!$B$42) | E13: ='Plan+'!G13 -> Destination_Plate_1 | F13: ='Plate organization+'!$A$13 -> mtp_source
... A97: =IF(C97="","",VLOOKUP(C97,Source_Plate!$I$2:$J$97,2,FALSE)) | B97: =IF(C97="","",'Plan+'!F97) | C97: =IF('Plan+'!C97="","",'Plan+'!C97) | D97: =IF(C97="","",'Plate organization+'!$B$42) | E97: ='Plan+'!G97 -> Destination_Plate_1 | F97: ='Plate organization+'!$A$13 -> mtp_source
B98: =COUNTA(B2:B97) -> 96

Sheet Worklist_MM
A1: Well Nr. source plate | B1: Well Nr. destination plate | C1: Part | D1: Volumen | E1: Destination_plate | F1: Source_plate
A2: =IF(C2="","",VLOOKUP(C2,Source_Plate!$A$2:$B$97,2,FALSE)) -> A03 | B2: =IF(C2="","",'Plan+'!F2) -> A01 | C2: =IF('Plan+'!D2="","",'Plan+'!D2) -> Mastermix1 | D2: =IF(C2="","",'Plate organization+'!$B$40) -> 40 | E2: ='Plan+'!G2 -> Destination_Plate_1 | F2: ='Plate organization+'!$A$13 -> mtp_source
A3: =IF(C3="","",VLOOKUP(C3,Source_Plate!$A$2:$B$97,2,FALSE)) -> A03 | B3: =IF(C3="","",'Plan+'!F3) -> B01 | C3: =IF('Plan+'!D3="","",'Plan+'!D3) -> Mastermix1 | D3: =IF(C3="","",'Plate organization+'!$B$40) -> 40 | E3: ='Plan+'!G3 -> Destination_Plate_1 | F3: ='Plate organization+'!$A$13 -> mtp_source
A4: =IF(C4="","",VLOOKUP(C4,Source_Plate!$A$2:$B$97,2,FALSE)) | B4: =IF(C4="","",'Plan+'!F4) | C4: =IF('Plan+'!D4="","",'Plan+'!D4) | D4: =IF(C4="","",'Plate organization+'!$B$40) | E4: ='Plan+'!G4 -> Destination_Plate_1 | F4: ='Plate organization+'!$A$13 -> mtp_source
A5: =IF(C5="","",VLOOKUP(C5,Source_Plate!$A$2:$B$97,2,FALSE)) | B5: =IF(C5="","",'Plan+'!F5) | C5: =IF('Plan+'!D5="","",'Plan+'!D5) | D5: =IF(C5="","",'Plate organization+'!$B$40) | E5: ='Plan+'!G5 -> Destination_Plate_1 | F5: ='Plate organization+'!$A$13 -> mtp_source
A6: =IF(C6="","",VLOOKUP(C6,Source_Plate!$A$2:$B$97,2,FALSE)) | B6: =IF(C6="","",'Plan+'!F6) | C6: =IF('Plan+'!D6="","",'Plan+'!D6) | D6: =IF(C6="","",'Plate organization+'!$B$40) | E6: ='Plan+'!G6 -> Destination_Plate_1 | F6: ='Plate organization+'!$A$13 -> mtp_source
A7: =IF(C7="","",VLOOKUP(C7,Source_Plate!$A$2:$B$97,2,FALSE)) | B7: =IF(C7="","",'Plan+'!F7) | C7: =IF('Plan+'!D7="","",'Plan+'!D7) | D7: =IF(C7="","",'Plate organization+'!$B$40) | E7: ='Plan+'!G7 -> Destination_Plate_1 | F7: ='Plate organization+'!$A$13 -> mtp_source
A8: =IF(C8="","",VLOOKUP(C8,Source_Plate!$A$2:$B$97,2,FALSE)) | B8: =IF(C8="","",'Plan+'!F8) | C8: =IF('Plan+'!D8="","",'Plan+'!D8) | D8: =IF(C8="","",'Plate organization+'!$B$40) | E8: ='Plan+'!G8 -> Destination_Plate_1 | F8: ='Plate organization+'!$A$13 -> mtp_source
A9: =IF(C9="","",VLOOKUP(C9,Source_Plate!$A$2:$B$97,2,FALSE)) | B9: =IF(C9="","",'Plan+'!F9) | C9: =IF('Plan+'!D9="","",'Plan+'!D9) | D9: =IF(C9="","",'Plate organization+'!$B$40) | E9: ='Plan+'!G9 -> Destination_Plate_1 | F9: ='Plate organization+'!$A$13 -> mtp_source
A10: =IF(C10="","",VLOOKUP(C10,Source_Plate!$A$2:$B$97,2,FALSE)) | B10: =IF(C10="","",'Plan+'!F10) | C10: =IF('Plan+'!D10="","",'Plan+'!D10) | D10: =IF(C10="","",'Plate organization+'!$B$40) | E10: ='Plan+'!G10 -> Destination_Plate_1 | F10: ='Plate organization+'!$A$13 -> mtp_source
A11: =IF(C11="","",VLOOKUP(C11,Source_Plate!$A$2:$B$97,2,FALSE)) | B11: =IF(C11="","",'Plan+'!F11) | C11: =IF('Plan+'!D11="","",'Plan+'!D11) | D11: =IF(C11="","",'Plate organization+'!$B$40) | E11: ='Plan+'!G11 -> Destination_Plate_1 | F11: ='Plate organization+'!$A$13 -> mtp_source
A12: =IF(C12="","",VLOOKUP(C12,Source_Plate!$A$2:$B$97,2,FALSE)) | B12: =IF(C12="","",'Plan+'!F12) | C12: =IF('Plan+'!D12="","",'Plan+'!D12) | D12: =IF(C12="","",'Plate organization+'!$B$40) | E12: ='Plan+'!G12 -> Destination_Plate_1 | F12: ='Plate organization+'!$A$13 -> mtp_source
A13: =IF(C13="","",VLOOKUP(C13,Source_Plate!$A$2:$B$97,2,FALSE)) | B13: =IF(C13="","",'Plan+'!F13) | C13: =IF('Plan+'!D13="","",'Plan+'!D13) | D13: =IF(C13="","",'Plate organization+'!$B$40) | E13: ='Plan+'!G13 -> Destination_Plate_1 | F13: ='Plate organization+'!$A$13 -> mtp_source
... A97: =IF(C97="","",VLOOKUP(C97,Source_Plate!$A$2:$B$97,2,FALSE)) | B97: =IF(C97="","",'Plan+'!F97) | C97: =IF('Plan+'!D97="","",'Plan+'!D97) | D97: =IF(C97="","",'Plate organization+'!$B$40) | E97: ='Plan+'!G97 -> Destination_Plate_1 | F97: ='Plate organization+'!$A$13 -> mtp_source
A98: =IF('Plan+'!#REF!="","",VLOOKUP(C98,Source_Plate!$A$2:$B$97,2,FALSE)) -> #REF! | B98: =COUNTA(B2:B97) -> 96

Sheet Worklist_PCR_Primer
A1: Well Nr. source plate | B1: Well Nr. destination plate | C1: Part | D1: Volumen | E1: Destination_plate | F1: Source_plate
A2: =IF(C2="","",VLOOKUP(C2,Source_Plate!$A$2:$B$97,2,FALSE)) -> A01 | B2: =IF(C2="","",'Plan+'!F2) -> A01 | C2: =IF('Plan+'!B2="","",'Plan+'!B2) -> UNS1_fwd und UNS4_rev | D2: =IF(C2="","",'Plate organization+'!$B$41) -> 5 | E2: ='Plan+'!G2 -> Destination_Plate_1 | F2: ='Plate organization+'!$A$13 -> mtp_source
A3: =IF(C3="","",VLOOKUP(C3,Source_Plate!$A$2:$B$97,2,FALSE)) -> B01 | B3: =IF(C3="","",'Plan+'!F3) -> B01 | C3: =IF('Plan+'!B3="","",'Plan+'!B3) -> UNS4_fwd und UNS10_rev | D3: =IF(C3="","",'Plate organization+'!$B$41) -> 5 | E3: ='Plan+'!G3 -> Destination_Plate_1 | F3: ='Plate organization+'!$A$13 -> mtp_source
A4: =IF(C4="","",VLOOKUP(C4,Source_Plate!$A$2:$B$97,2,FALSE)) | B4: =IF(C4="","",'Plan+'!F4) | C4: =IF('Plan+'!B4="","",'Plan+'!B4) | D4: =IF(C4="","",'Plate organization+'!$B$41) | E4: ='Plan+'!G4 -> Destination_Plate_1 | F4: ='Plate organization+'!$A$13 -> mtp_source
A5: =IF(C5="","",VLOOKUP(C5,Source_Plate!$A$2:$B$97,2,FALSE)) | B5: =IF(C5="","",'Plan+'!F5) | C5: =IF('Plan+'!B5="","",'Plan+'!B5) | D5: =IF(C5="","",'Plate organization+'!$B$41) | E5: ='Plan+'!G5 -> Destination_Plate_1 | F5: ='Plate organization+'!$A$13 -> mtp_source
A6: =IF(C6="","",VLOOKUP(C6,Source_Plate!$A$2:$B$97,2,FALSE)) | B6: =IF(C6="","",'Plan+'!F6) | C6: =IF('Plan+'!B6="","",'Plan+'!B6) | D6: =IF(C6="","",'Plate organization+'!$B$41) | E6: ='Plan+'!G6 -> Destination_Plate_1 | F6: ='Plate organization+'!$A$13 -> mtp_source
A7: =IF(C7="","",VLOOKUP(C7,Source_Plate!$A$2:$B$97,2,FALSE)) | B7: =IF(C7="","",'Plan+'!F7) | C7: =IF('Plan+'!B7="","",'Plan+'!B7) | D7: =IF(C7="","",'Plate organization+'!$B$41) | E7: ='Plan+'!G7 -> Destination_Plate_1 | F7: ='Plate organization+'!$A$13 -> mtp_source
A8: =IF(C8="","",VLOOKUP(C8,Source_Plate!$A$2:$B$97,2,FALSE)) | B8: =IF(C8="","",'Plan+'!F8) | C8: =IF('Plan+'!B8="","",'Plan+'!B8) | D8: =IF(C8="","",'Plate organization+'!$B$41) | E8: ='Plan+'!G8 -> Destination_Plate_1 | F8: ='Plate organization+'!$A$13 -> mtp_source
A9: =IF(C9="","",VLOOKUP(C9,Source_Plate!$A$2:$B$97,2,FALSE)) | B9: =IF(C9="","",'Plan+'!F9) | C9: =IF('Plan+'!B9="","",'Plan+'!B9) | D9: =IF(C9="","",'Plate organization+'!$B$41) | E9: ='Plan+'!G9 -> Destination_Plate_1 | F9: ='Plate organization+'!$A$13 -> mtp_source
A10: =IF(C10="","",VLOOKUP(C10,Source_Plate!$A$2:$B$97,2,FALSE)) | B10: =IF(C10="","",'Plan+'!F10) | C10: =IF('Plan+'!B10="","",'Plan+'!B10) | D10: =IF(C10="","",'Plate organization+'!$B$41) | E10: ='Plan+'!G10 -> Destination_Plate_1 | F10: ='Plate organization+'!$A$13 -> mtp_source
A11: =IF(C11="","",VLOOKUP(C11,Source_Plate!$A$2:$B$97,2,FALSE)) | B11: =IF(C11="","",'Plan+'!F11) | C11: =IF('Plan+'!B11="","",'Plan+'!B11) | D11: =IF(C11="","",'Plate organization+'!$B$41) | E11: ='Plan+'!G11 -> Destination_Plate_1 | F11: ='Plate organization+'!$A$13 -> mtp_source
A12: =IF(C12="","",VLOOKUP(C12,Source_Plate!$A$2:$B$97,2,FALSE)) | B12: =IF(C12="","",'Plan+'!F12) | C12: =IF('Plan+'!B12="","",'Plan+'!B12) | D12: =IF(C12="","",'Plate organization+'!$B$41) | E12: ='Plan+'!G12 -> Destination_Plate_1 | F12: ='Plate organization+'!$A$13 -> mtp_source
A13: =IF(C13="","",VLOOKUP(C13,Source_Plate!$A$2:$B$97,2,FALSE)) | B13: =IF(C13="","",'Plan+'!F13) | C13: =IF('Plan+'!B13="","",'Plan+'!B13) | D13: =IF(C13="","",'Plate organization+'!$B$41) | E13: ='Plan+'!G13 -> Destination_Plate_1 | F13: ='Plate organization+'!$A$13 -> mtp_source
... A97: =IF(C97="","",VLOOKUP(C97,Source_Plate!$A$2:$B$97,2,FALSE)) | B97: =IF(C97="","",'Plan+'!F97) | C97: =IF('Plan+'!B97="","",'Plan+'!B97) | D97: =IF(C97="","",'Plate organization+'!$B$41) | E97: ='Plan+'!G97 -> Destination_Plate_1 | F97: ='Plate organization+'!$A$13 -> mtp_source
A98: =IF('Plan+'!#REF!="","",VLOOKUP(C98,Source_Plate!$A$2:$B$97,2,FALSE)) -> #REF! | B98: =COUNTA(B2:B97) -> 96

Sheet Worklist_Primer1
A1: Well Nr. source plate | B1: Well Nr. destination plate | C1: Part | D1: Volumen | E1: Destination_plate | F1: Source_Plate
A2: =IF(C2="","",VLOOKUP(C2,Source_Plate!$E$2:$F$97,2,FALSE)) -> A01 | B2: =IF(C2="","",'PM_info+'!B2) -> A01 | C2: =IF('PM_info+'!D2="","",'PM_info+'!D2) -> UNS1_fwd | D2: =IF(C2="","",'Plate organization+'!$B$38) -> 10 | E2: ='Plate organization+'!$A$13 -> mtp_source | F2: ='Plate organization+'!$A$1 -> mtp_primer_stocks
A3: =IF(C3="","",VLOOKUP(C3,Source_Plate!$E$2:$F$97,2,FALSE)) -> C01 | B3: =IF(C3="","",'PM_info+'!B3) -> B01 | C3: =IF('PM_info+'!D3="","",'PM_info+'!D3) -> UNS4_fwd | D3: =IF(C3="","",'Plate organization+'!$B$38) -> 10 | E3: ='Plate organization+'!$A$13 -> mtp_source | F3: ='Plate organization+'!$A$1 -> mtp_primer_stocks
A4: =IF(C4="","",VLOOKUP(C4,Source_Plate!$E$2:$F$97,2,FALSE)) | B4: =IF(C4="","",'PM_info+'!B4) | C4: =IF('PM_info+'!D4="","",'PM_info+'!D4) | D4: =IF(C4="","",'Plate organization+'!$B$38) | E4: ='Plate organization+'!$A$13 -> mtp_source | F4: ='Plate organization+'!$A$1 -> mtp_primer_stocks
A5: =IF(C5="","",VLOOKUP(C5,Source_Plate!$E$2:$F$97,2,FALSE)) | B5: =IF(C5="","",'PM_info+'!B5) | C5: =IF('PM_info+'!D5="","",'PM_info+'!D5) | D5: =IF(C5="","",'Plate organization+'!$B$38) | E5: ='Plate organization+'!$A$13 -> mtp_source | F5: ='Plate organization+'!$A$1 -> mtp_primer_stocks
A6: =IF(C6="","",VLOOKUP(C6,Source_Plate!$E$2:$F$97,2,FALSE)) | B6: =IF(C6="","",'PM_info+'!B6) | C6: =IF('PM_info+'!D6="","",'PM_info+'!D6) | D6: =IF(C6="","",'Plate organization+'!$B$38) | E6: ='Plate organization+'!$A$13 -> mtp_source | F6: ='Plate organization+'!$A$1 -> mtp_primer_stocks
A7: =IF(C7="","",VLOOKUP(C7,Source_Plate!$E$2:$F$97,2,FALSE)) | B7: =IF(C7="","",'PM_info+'!B7) | C7: =IF('PM_info+'!D7="","",'PM_info+'!D7) | D7: =IF(C7="","",'Plate organization+'!$B$38) | E7: ='Plate organization+'!$A$13 -> mtp_source | F7: ='Plate organization+'!$A$1 -> mtp_primer_stocks
A8: =IF(C8="","",VLOOKUP(C8,Source_Plate!$E$2:$F$97,2,FALSE)) | B8: =IF(C8="","",'PM_info+'!B8) | C8: =IF('PM_info+'!D8="","",'PM_info+'!D8) | D8: =IF(C8="","",'Plate organization+'!$B$38) | E8: ='Plate organization+'!$A$13 -> mtp_source | F8: ='Plate organization+'!$A$1 -> mtp_primer_stocks
A9: =IF(C9="","",VLOOKUP(C9,Source_Plate!$E$2:$F$97,2,FALSE)) | B9: =IF(C9="","",'PM_info+'!B9) | C9: =IF('PM_info+'!D9="","",'PM_info+'!D9) | D9: =IF(C9="","",'Plate organization+'!$B$38) | E9: ='Plate organization+'!$A$13 -> mtp_source | F9: ='Plate organization+'!$A$1 -> mtp_primer_stocks
A10: =IF(C10="","",VLOOKUP(C10,Source_Plate!$E$2:$F$97,2,FALSE)) | B10: =IF(C10="","",'PM_info+'!B10) | C10: =IF('PM_info+'!D10="","",'PM_info+'!D10) | D10: =IF(C10="","",'Plate organization+'!$B$38) | E10: ='Plate organization+'!$A$13 -> mtp_source | F10: ='Plate organization+'!$A$1 -> mtp_primer_stocks
A11: =IF(C11="","",VLOOKUP(C11,Source_Plate!$E$2:$F$97,2,FALSE)) | B11: =IF(C11="","",'PM_info+'!B11) | C11: =IF('PM_info+'!D11="","",'PM_info+'!D11) | D11: =IF(C11="","",'Plate organization+'!$B$38) | E11: ='Plate organization+'!$A$13 -> mtp_source | F11: ='Plate organization+'!$A$1 -> mtp_primer_stocks
A12: =IF(C12="","",VLOOKUP(C12,Source_Plate!$E$2:$F$97,2,FALSE)) | B12: =IF(C12="","",'PM_info+'!B12) | C12: =IF('PM_info+'!D12="","",'PM_info+'!D12) | D12: =IF(C12="","",'Plate organization+'!$B$38) | E12: ='Plate organization+'!$A$13 -> mtp_source | F12: ='Plate organization+'!$A$1 -> mtp_primer_stocks
A13: =IF(C13="","",VLOOKUP(C13,Source_Plate!$E$2:$F$97,2,FALSE)) | B13: =IF(C13="","",'PM_info+'!B13) | C13: =IF('PM_info+'!D13="","",'PM_info+'!D13) | D13: =IF(C13="","",'Plate organization+'!$B$38) | E13: ='Plate organization+'!$A$13 -> mtp_source | F13: ='Plate organization+'!$A$1 -> mtp_primer_stocks
... A97: =IF(C97="","",VLOOKUP(C97,Source_Plate!$E$2:$F$97,2,FALSE)) | B97: =IF(C97="","",'PM_info+'!B97) | C97: =IF('PM_info+'!D97="","",'PM_info+'!D97) | D97: =IF(C97="","",'Plate organization+'!$B$38) | E97: ='Plate organization+'!$A$13 -> mtp_source | F97: ='Plate organization+'!$A$1 -> mtp_primer_stocks

Sheet Worklist_Primer2
A1: Well Nr. source plate | B1: Well Nr. destination plate | C1: Part | D1: Volumen | E1: Destination_plate | F1: Source_Plate
A2: =IF(C2="","",VLOOKUP(C2,Source_Plate!$E$2:$F$97,2,FALSE)) -> B01 | B2: =IF(C2="","",'PM_info+'!B2) -> A01 | C2: =IF('PM_info+'!E2="","",'PM_info+'!E2) -> UNS4_rev | D2: =IF(C2="","",'Plate organization+'!$B$38) -> 10 | E2: ='Plate organization+'!$A$13 -> mtp_source | F2: ='Plate organization+'!$A$1 -> mtp_primer_stocks
A3: =IF(C3="","",VLOOKUP(C3,Source_Plate!$E$2:$F$97,2,FALSE)) -> D01 | B3: =IF(C3="","",'PM_info+'!B3) -> B01 | C3: =IF('PM_info+'!E3="","",'PM_info+'!E3) -> UNS10_rev | D3: =IF(C3="","",'Plate organization+'!$B$38) -> 10 | E3: ='Plate organization+'!$A$13 -> mtp_source | F3: ='Plate organization+'!$A$1 -> mtp_primer_stocks
A4: =IF(C4="","",VLOOKUP(C4,Source_Plate!$E$2:$F$97,2,FALSE)) | B4: =IF(C4="","",'PM_info+'!B4) | C4: =IF('PM_info+'!E4="","",'PM_info+'!E4) | D4: =IF(C4="","",'Plate organization+'!$B$38) | E4: ='Plate organization+'!$A$13 -> mtp_source | F4: ='Plate organization+'!$A$1 -> mtp_primer_stocks
A5: =IF(C5="","",VLOOKUP(C5,Source_Plate!$E$2:$F$97,2,FALSE)) | B5: =IF(C5="","",'PM_info+'!B5) | C5: =IF('PM_info+'!E5="","",'PM_info+'!E5) | D5: =IF(C5="","",'Plate organization+'!$B$38) | E5: ='Plate organization+'!$A$13 -> mtp_source | F5: ='Plate organization+'!$A$1 -> mtp_primer_stocks
A6: =IF(C6="","",VLOOKUP(C6,Source_Plate!$E$2:$F$97,2,FALSE)) | B6: =IF(C6="","",'PM_info+'!B6) | C6: =IF('PM_info+'!E6="","",'PM_info+'!E6) | D6: =IF(C6="","",'Plate organization+'!$B$38) | E6: ='Plate organization+'!$A$13 -> mtp_source | F6: ='Plate organization+'!$A$1 -> mtp_primer_stocks
A7: =IF(C7="","",VLOOKUP(C7,Source_Plate!$E$2:$F$97,2,FALSE)) | B7: =IF(C7="","",'PM_info+'!B7) | C7: =IF('PM_info+'!E7="","",'PM_info+'!E7) | D7: =IF(C7="","",'Plate organization+'!$B$38) | E7: ='Plate organization+'!$A$13 -> mtp_source | F7: ='Plate organization+'!$A$1 -> mtp_primer_stocks
A8: =IF(C8="","",VLOOKUP(C8,Source_Plate!$E$2:$F$97,2,FALSE)) | B8: =IF(C8="","",'PM_info+'!B8) | C8: =IF('PM_info+'!E8="","",'PM_info+'!E8) | D8: =IF(C8="","",'Plate organization+'!$B$38) | E8: ='Plate organization+'!$A$13 -> mtp_source | F8: ='Plate organization+'!$A$1 -> mtp_primer_stocks
A9: =IF(C9="","",VLOOKUP(C9,Source_Plate!$E$2:$F$97,2,FALSE)) | B9: =IF(C9="","",'PM_info+'!B9) | C9: =IF('PM_info+'!E9="","",'PM_info+'!E9) | D9: =IF(C9="","",'Plate organization+'!$B$38) | E9: ='Plate organization+'!$A$13 -> mtp_source | F9: ='Plate organization+'!$A$1 -> mtp_primer_stocks
A10: =IF(C10="","",VLOOKUP(C10,Source_Plate!$E$2:$F$97,2,FALSE)) | B10: =IF(C10="","",'PM_info+'!B10) | C10: =IF('PM_info+'!E10="","",'PM_info+'!E10) | D10: =IF(C10="","",'Plate organization+'!$B$38) | E10: ='Plate organization+'!$A$13 -> mtp_source | F10: ='Plate organization+'!$A$1 -> mtp_primer_stocks
A11: =IF(C11="","",VLOOKUP(C11,Source_Plate!$E$2:$F$97,2,FALSE)) | B11: =IF(C11="","",'PM_info+'!B11) | C11: =IF('PM_info+'!E11="","",'PM_info+'!E11) | D11: =IF(C11="","",'Plate organization+'!$B$38) | E11: ='Plate organization+'!$A$13 -> mtp_source | F11: ='Plate organization+'!$A$1 -> mtp_primer_stocks
A12: =IF(C12="","",VLOOKUP(C12,Source_Plate!$E$2:$F$97,2,FALSE)) | B12: =IF(C12="","",'PM_info+'!B12) | C12: =IF('PM_info+'!E12="","",'PM_info+'!E12) | D12: =IF(C12="","",'Plate organization+'!$B$38) | E12: ='Plate organization+'!$A$13 -> mtp_source | F12: ='Plate organization+'!$A$1 -> mtp_primer_stocks
A13: =IF(C13="","",VLOOKUP(C13,Source_Plate!$E$2:$F$97,2,FALSE)) | B13: =IF(C13="","",'PM_info+'!B13) | C13: =IF('PM_info+'!E13="","",'PM_info+'!E13) | D13: =IF(C13="","",'Plate organization+'!$B$38) | E13: ='Plate organization+'!$A$13 -> mtp_source | F13: ='Plate organization+'!$A$1 -> mtp_primer_stocks
... A97: =IF(C97="","",VLOOKUP(C97,Source_Plate!$E$2:$F$97,2,FALSE)) | B97: =IF(C97="","",'PM_info+'!B97) | C97: =IF('PM_info+'!E97="","",'PM_info+'!E97) | D97: =IF(C97="","",'Plate organization+'!$B$38) | E97: ='Plate organization+'!$A$13 -> mtp_source | F97: ='Plate organization+'!$A$1 -> mtp_primer_stocks
